Workbook

Sheet PRESUPUESTO DE OBRA
A1: sub partidas | B1: partida | C1: PC | D1: Descripción | E1: Und. | G1: Metrado - REV 09 | H1: PU MO - REV 09 | I1: PU MAT - REV 09 | J1: PU EQ - REV 09 | K1: PU SC - REV 09 | L1: PU - REV 09 | M1: SUBTOTAL - REV 09
C2: 01 | D2: OBRAS PRELIMINARES Y PROVISIONALES | M2: =+M3+M54 -> 2164843.1
C3: 01.01 | D3: OBRAS PRELIMINARES | E3: T | M3: =+M4+M7+M9+M12+M17+M19+M24+M27+M29+M32+M34+M36+M44+M48+M51 -> 1065201.2
C4: 01.01.01 | D4: TRASLADO DE EQUIPO DE MATERIALES Y HERRAMIENTAS A OBRA | E4: TT | M4: =SUM(M5:M6) -> 21000
B5: varios - Obras Preliminares | C5: 01.01.01.01 | D5: MOVILIZACIÓN DE EQUIPO DE MATERIALES Y HERRAMIENTAS A OBRA | E5: gbl | G5: 3 | K5: 4000 | L5: =+SUM(H5:K5) -> 4000 | M5: =+L5*G5 -> 12000
B6: varios - Obras Preliminares | C6: 01.01.01.02 | D6: DESMOVILIZACIÓN DE EQUIPOS Y HERRAMIENTAS | E6: gbl | G6: 3 | K6: 3000 | L6: =+SUM(H6:K6) -> 3000 | M6: =+L6*G6 -> 9000
C7: 01.01.02 | D7: RED PROVISIONAL PARA AGUA | E7: TT | L7: =+SUM(H7:K7) -> 0 | M7: =SUM(M8) -> 3000
B8: Servicios, Energia, Agua y Comunicaciones | C8: 01.01.02.01 | D8: RED PROVISIONAL PARA AGUA | E8: gbl | G8: 3 | K8: 1000 | L8: =+SUM(H8:K8) -> 1000 | M8: =+L8*G8 -> 3000
C9: 01.01.03 | D9: RED PROVISIONAL PARA AGUA | E9: TT | L9: =+SUM(H9:K9) -> 0 | M9: =SUM(M10:M11) -> 98850
B10: Servicios, Energia, Agua y Comunicaciones | C10: 01.01.03.01 | D10: RED PROVISIONAL DE ENERGÍA ELÉCTRICA | E10: gbl | G10: 3 | K10: 32500 | L10: =+SUM(H10:K10) -> 32500 | M10: =+L10*G10 -> 97500
B11: Servicios, Energia, Agua y Comunicaciones | C11: 01.01.03.02 | D11: POZO A TIERRA ENERGÍA ELÉCTRICA PROVISIONAL | E11: gbl | G11: 3 | K11: 450 | L11: =+SUM(H11:K11) -> 450 | M11: =+L11*G11 -> 1350
C12: 01.01.04 | D12: CASETA PARA OFICINAS, ALMACÉN, VESTUARIOS Y GUARDIANÍA | E12: TT | L12: =+SUM(H12:K12) -> 0 | M12: =SUM(M13:M16) -> 54350
B13: Caseta para Oficinas, comedor y Cerco perimetrico | C13: 01.01.04.01 | D13: CASETA PARA OFICINAS, ALMACÉN, VESTUARIOS Y GUARDIANÍA | E13: gbl | G13: 3 | K13: 6500 | L13: =+SUM(H13:K13) -> 6500 | M13: =+L13*G13 -> 19500
B14: Caseta para Oficinas, comedor y Cerco perimetrico | C14: 01.01.04.02 | D14: MOVILIZACION Y DESMOV CONTENEDOR | E14: gbl | G14: 3 | K14: 1200 | L14: =+SUM(H14:K14) -> 1200 | M14: =+L14*G14 -> 3600
B15: Caseta para Oficinas, comedor y Cerco perimetrico | C15: 01.01.04.03 | D15: ALQUILER MENSUAL DE CONTENEDOR | E15: mes | G15: 7 | K15: 4150 | L15: =+SUM(H15:K15) -> 4150 | M15: =+L15*G15 -> 29050
B16: Caseta para Oficinas, comedor y Cerco perimetrico | C16: 01.01.04.04 | D16: REUBICACIÓN POR PROCESO CONSTRUCTIVO CASETA PARA OFICINAS, ALMACÉN, VESTUARIOS Y GUARDIANÍA | E16: gbl | G16: 1 | K16: 2200 | L16: =+SUM(H16:K16) -> 2200 | M16: =+L16*G16 -> 2200
C17: 01.01.05 | D17: COMEDOR PROVISIONAL DE OBRA | E17: TT | L17: =+SUM(H17:K17) -> 0 | M17: =SUM(M18) -> 1050
B18: varios - Obras Preliminares | C18: 01.01.05.01 | D18: COMEDOR PROVISIONAL | E18: gbl | G18: 3 | K18: 350 | L18: =+SUM(H18:K18) -> 350 | M18: =+L18*G18 -> 1050
C19: 01.01.06 | D19: MONTAJE Y DESMONTAJE DE CERCO PERIMÉTRICO DE OBRA | E19: TT | L19: =+SUM(H19:K19) -> 0 | M19: =SUM(M20:M23) -> 29860.5
B20: Caseta para Oficinas, comedor y Cerco perimetrico | C20: 01.01.06.01 | D20: MONTAJE Y DESMONTAJE DE CERCO PERIMÉTRICO DE OBRA | E20: m | G20: 132.06 | K20: 150 | L20: =+SUM(H20:K20) -> 150 | M20: =+L20*G20 -> 19809
B21: Caseta para Oficinas, comedor y Cerco perimetrico | C21: 01.01.06.02 | D21: MANTENIMIENTO DE CERCO PERIMÉTRICO | E21: gbl | G21: 6 | K21: 1000 | L21: =+SUM(H21:K21) -> 1000 | M21: =+L21*G21 -> 6000
B22: Caseta para Oficinas, comedor y Cerco perimetrico | C22: 01.01.06.03 | D22: MALLA RASHEL EN TODO EL PERÍMETRO | E22: m | G22: 132.06 | K22: 25 | L22: =+SUM(H22:K22) -> 25 | M22: =+L22*G22 -> 3301.5
B23: varios - Obras Preliminares | C23: 01.01.06.04 | D23: CARTEL INFORMATIVO DE OBRA | E23: gbl | G23: 1 | K23: 750 | L23: =+SUM(H23:K23) -> 750 | M23: =+L23*G23 -> 750
C24: 01.01.07 | D24: SERVICIOS HIGIÉNICOS PARA STAFF Y OBREROS | E24: TT | L24: =+SUM(H24:K24) -> 0 | M24: =SUM(M25:M26) -> 24395
B25: Servicios Higienicos para Staff y Obreros | C25: 01.01.07.01 | D25: SERVICIOS HIGIÉNICOS PARA OBREROS | E25: mes | G25: 17 | H25: 125 | I25: 160 | K25: 840 | L25: =+SUM(H25:K25) -> 1125 | M25: =+L25*G25 -> 19125
B26: Servicios Higienicos para Staff y Obreros | C26: 01.01.07.02 | D26: SERVICIOS HIGIÉNICOS PARA STAFF | E26: mes | G26: 17 | K26: 310 | L26: =+SUM(H26:K26) -> 310 | M26: =+L26*G26 -> 5270
C27: 01.01.08 | D27: ALQUILER DE DUCHAS PORTÁTILES | E27: TT | L27: =+SUM(H27:K27) -> 0 | M27: =SUM(M28) -> 11679
B28: Servicios Higienicos para Staff y Obreros | C28: 01.01.08.01 | D28: ALQUILER DE DUCHAS PORTÁTILES | E28: mes | G28: 17 | K28: 687 | L28: =+SUM(H28:K28) -> 687 | M28: =+L28*G28 -> 11679
C29: 01.01.09 | D29: AMPLIACIÓN DE CARGA ELÉCTRICA PROVISIONAL | E29: TT | L29: =+SUM(H29:K29) -> 0 | M29: =SUM(M30:M31) -> 8505
B30: Servicios, Energia, Agua y Comunicaciones | C30: 01.01.09.01 | D30: AMPLIACIÓN DE CARGA ELÉCTRICA PROVISIONAL | E30: gbl | G30: 1 | K30: 1000 | L30: =+SUM(H30:K30) -> 1000 | M30: =+L30*G30 -> 1000
B31: Servicios, Energia, Agua y Comunicaciones | D31: GRUPO ELECTROGENO 200 KW | E31: mes | G31: 5 | I31: 1 | K31: 1500 | L31: =+SUM(H31:K31) -> 1501 | M31: =+L31*G31 -> 7505
C32: 01.01.10 | D32: CIMENTACIÓN DE TORRE GRÚA | E32: TT | L32: =+SUM(H32:K32) -> 0 | M32: =SUM(M33) -> 20500
B33: Traslado Vertical y Horizontal | C33: 01.01.10.01 | D33: CIMENTACIÓN DE TORRE GRÚA | E33: gbl | G33: 1 | K33: 20500 | L33: =+SUM(H33:K33) -> 20500 | M33: =+L33*G33 -> 20500
C34: 01.01.11 | D34: SUMINISTRO DE ENERGÍA ELÉCTRICA PARA LA TORRE GRÚA | E34: TT | L34: =+SUM(H34:K34) -> 0 | M34: =SUM(M35) -> 25000
B35: Traslado Vertical y Horizontal | C35: 01.01.11.01 | D35: SUMINISTRO DE ENERGÍA ELÉCTRICA PARA LA TORRE GRÚA | E35: mes | G35: 10 | K35: 2500 | L35: =+SUM(H35:K35) -> 2500 | M35: =+L35*G35 -> 25000
C36: 01.01.12 | D36: TRANSPORTE VERTICAL - HORIZONTAL | E36: TT | L36: =+SUM(H36:K36) -> 0 | M36: =SUM(M37:M43) -> 513359.07
B37: Traslado Vertical y Horizontal | C37: 01.01.12.01 | D37: MONTAJE Y DESMONTAJE TORRE GRUA | E37: gbl | G37: 1 | K37: 100003.75 | L37: =+SUM(H37:K37) -> 100003.75 | M37: =+L37*G37 -> 100003.75
B38: Traslado Vertical y Horizontal | C38: 01.01.12.02 | D38: ALQUILER DE TORRE GRÚA | E38: mes | G38: 10 | K38: 22060.5 | L38: =+SUM(H38:K38) -> 22060.5 | M38: =+L38*G38 -> 220605
B39: Traslado Vertical y Horizontal | C39: 01.01.12.03 | D39: ARMADO Y DESARMADO DE PLATAFORMAS EN VOLADIZO PARA GRÚA (INSTALACIÓN DE ESCUADRAS METÁLICAS) | E39: gbl | G39: 3 | K39: 6318.16 | L39: =+SUM(H39:K39) -> 6318.16 | M39: =+L39*G39 -> 18954.48
B40: Traslado Vertical y Horizontal | C40: 01.01.12.04 | D40: ACARREO HORIZONTAL PERSONAL | E40: mes | G40: 17 | K40: 4811.52 | L40: =+SUM(H40:K40) -> 4811.52 | M40: =+L40*G40 -> 81795.84
...

Sheet TAREO SEMANAL
A2: REPORTE DE TAREO DE PERSONAL OBRERO
F4: 2 | G4: Del: | H4: 45711 | K4: Al: | L4: =+H4+5 -> 45716
A5: Obra | B5: LITORAL 900
A6: Cliente | B6: INVERSIONES SAURIS SAC
A7: Nº | B7: APELLIDOS | C7: NOMBRES | D7: DNI | E7: CATEGORIA | F7: ESPECIALIDAD | G7: =+F4 -> 2 | S7: TOTAL DE HORAS NORMALES | T7: TOTAL DE HORAS EXTRAS | U7: HORAS EXTRAS AL 60% | V7: HORAS EXTRAS AL 100% | W7: TOTAL DE HORAS TRABAJADAS
G8: LUNES | I8: MARTES | K8: MIERCOLES | M8: JUEVES | O8: VIERNES | Q8: SABADO
G9: =H4 -> 45711 | I9: =+G9+1 -> 45712 | K9: =+I9+1 -> 45713 | M9: =+K9+1 -> 45714 | O9: =+M9+1 -> 45715 | Q9: =+O9+1 -> 45716
G10: HN | H10: Ext | I10: HN | J10: Ext | K10: HN | L10: Ext | M10: HN | N10: Ext | O10: HN | P10: Ext. | Q10: HN | R10: Ext.
A11: 1 | B11: PEREZ GALLEGOS | C11: JORGE ANDRES | D11: 48244396 | E11: PEON | F11: CONCRETO MUROS ANCLADOS | G11: 8.5 | I11: 8.5 | K11: 8.5 | M11: 8.5 | O11: 8.5 | Q11: 5.5 | S11: =G11+I11+K11+M11+O11+Q11 -> 48 | T11: =H11+J11+L11+N11+P11+R11 -> 0 | U11: =IF(H11>2,2,H11)+IF(J11>2,2,J11)+IF(L11>2,2,L11)+IF(N11>2,2,N11)+IF(P11>2,2,P11)+IF(R11>2,2,R11) -> 0 | V11: =T11-U11 -> 0 | W11: =S11+T11 -> 48
A12: =+A11+1 -> 2 | B12: SANCHEZ BUSTAMANTE | C12: DAVID GONZALO | D12: 48987299 | E12: PEON | F12: CONCRETO ESTACIONAMIENTOS | G12: 8.5 | I12: 8.5 | K12: 8.5 | M12: 8.5 | O12: 8.5 | Q12: 5.5 | S12: =G12+I12+K12+M12+O12+Q12 -> 48 | T12: =H12+J12+L12+N12+P12+R12 -> 0 | U12: =IF(H12>2,2,H12)+IF(J12>2,2,J12)+IF(L12>2,2,L12)+IF(N12>2,2,N12)+IF(P12>2,2,P12)+IF(R12>2,2,R12) -> 0 | V12: =T12-U12 -> 0 | W12: =S12+T12 -> 48
A13: =+A12+1 -> 3 | B13: SANDOVAL CONDORI | C13: VICTOR ANGEL | D13: 25807626 | E13: PEON | F13: SINDICATO | G13: 8.5 | I13: 8.5 | K13: 8.5 | M13: 8.5 | O13: 8.5 | Q13: 5.5 | S13: =G13+I13+K13+M13+O13+Q13 -> 48 | T13: =H13+J13+L13+N13+P13+R13 -> 0 | U13: =IF(H13>2,2,H13)+IF(J13>2,2,J13)+IF(L13>2,2,L13)+IF(N13>2,2,N13)+IF(P13>2,2,P13)+IF(R13>2,2,R13) -> 0 | V13: =T13-U13 -> 0 | W13: =S13+T13 -> 48
A14: =+A13+1 -> 4 | B14: ELME MORAN | C14: JOHN JORGE | D14: 40426251 | E14: OPERARIO | F14: TOPOGRAFIA | G14: 8.5 | I14: 8.5 | K14: 8.5 | M14: 8.5 | O14: 8.5 | Q14: 5.5 | S14: =G14+I14+K14+M14+O14+Q14 -> 48 | T14: =H14+J14+L14+N14+P14+R14 -> 0 | U14: =IF(H14>2,2,H14)+IF(J14>2,2,J14)+IF(L14>2,2,L14)+IF(N14>2,2,N14)+IF(P14>2,2,P14)+IF(R14>2,2,R14) -> 0 | V14: =T14-U14 -> 0 | W14: =S14+T14 -> 48
A15: =+A14+1 -> 5 | B15: ELME CURIPACO | C15: DIETRICH RODRIGO | D15: 70702879 | E15: PEON | F15: TOPOGRAFIA | G15: 8.5 | I15: 8.5 | K15: 8.5 | M15: 8.5 | O15: 8.5 | Q15: 5.5 | S15: =G15+I15+K15+M15+O15+Q15 -> 48 | T15: =H15+J15+L15+N15+P15+R15 -> 0 | U15: =IF(H15>2,2,H15)+IF(J15>2,2,J15)+IF(L15>2,2,L15)+IF(N15>2,2,N15)+IF(P15>2,2,P15)+IF(R15>2,2,R15) -> 0 | V15: =T15-U15 -> 0 | W15: =S15+T15 -> 48
A16: =+A15+1 -> 6 | B16: CHUQUILIN ANGULO | C16: OSCAR JUNIOR | D16: 76214091 | E16: OPERARIO | F16: MONITOR | G16: 8.5 | I16: 8.5 | K16: 8.5 | M16: 8.5 | O16: 8.5 | Q16: 5.5 | S16: =G16+I16+K16+M16+O16+Q16 -> 48 | T16: =H16+J16+L16+N16+P16+R16 -> 0 | U16: =IF(H16>2,2,H16)+IF(J16>2,2,J16)+IF(L16>2,2,L16)+IF(N16>2,2,N16)+IF(P16>2,2,P16)+IF(R16>2,2,R16) -> 0 | V16: =T16-U16 -> 0 | W16: =S16+T16 -> 48
A17: =+A16+1 -> 7 | S17: =G17+I17+K17+M17+O17+Q17 -> 0 | T17: =H17+J17+L17+N17+P17+R17 -> 0 | U17: =IF(H17>2,2,H17)+IF(J17>2,2,J17)+IF(L17>2,2,L17)+IF(N17>2,2,N17)+IF(P17>2,2,P17)+IF(R17>2,2,R17) -> 0 | V17: =T17-U17 -> 0 | W17: =S17+T17 -> 0
A18: =+A17+1 -> 8 | S18: =G18+I18+K18+M18+O18+Q18 -> 0 | T18: =H18+J18+L18+N18+P18+R18 -> 0 | U18: =IF(H18>2,2,H18)+IF(J18>2,2,J18)+IF(L18>2,2,L18)+IF(N18>2,2,N18)+IF(P18>2,2,P18)+IF(R18>2,2,R18) -> 0 | V18: =T18-U18 -> 0 | W18: =S18+T18 -> 0
A19: =+A18+1 -> 9 | S19: =G19+I19+K19+M19+O19+Q19 -> 0 | T19: =H19+J19+L19+N19+P19+R19 -> 0 | U19: =IF(H19>2,2,H19)+IF(J19>2,2,J19)+IF(L19>2,2,L19)+IF(N19>2,2,N19)+IF(P19>2,2,P19)+IF(R19>2,2,R19) -> 0 | V19: =T19-U19 -> 0 | W19: =S19+T19 -> 0
A20: =+A19+1 -> 10 | S20: =G20+I20+K20+M20+O20+Q20 -> 0 | T20: =H20+J20+L20+N20+P20+R20 -> 0 | U20: =IF(H20>2,2,H20)+IF(J20>2,2,J20)+IF(L20>2,2,L20)+IF(N20>2,2,N20)+IF(P20>2,2,P20)+IF(R20>2,2,R20) -> 0 | V20: =T20-U20 -> 0 | W20: =S20+T20 -> 0
A21: =+A20+1 -> 11 | S21: =G21+I21+K21+M21+O21+Q21 -> 0 | T21: =H21+J21+L21+N21+P21+R21 -> 0 | U21: =IF(H21>2,2,H21)+IF(J21>2,2,J21)+IF(L21>2,2,L21)+IF(N21>2,2,N21)+IF(P21>2,2,P21)+IF(R21>2,2,R21) -> 0 | V21: =T21-U21 -> 0 | W21: =S21+T21 -> 0
A22: =+A21+1 -> 12 | S22: =G22+I22+K22+M22+O22+Q22 -> 0 | T22: =H22+J22+L22+N22+P22+R22 -> 0 | U22: =IF(H22>2,2,H22)+IF(J22>2,2,J22)+IF(L22>2,2,L22)+IF(N22>2,2,N22)+IF(P22>2,2,P22)+IF(R22>2,2,R22) -> 0 | V22: =T22-U22 -> 0 | W22: =S22+T22 -> 0
A23: =+A22+1 -> 13 | S23: =G23+I23+K23+M23+O23+Q23 -> 0 | T23: =H23+J23+L23+N23+P23+R23 -> 0 | U23: =IF(H23>2,2,H23)+IF(J23>2,2,J23)+IF(L23>2,2,L23)+IF(N23>2,2,N23)+IF(P23>2,2,P23)+IF(R23>2,2,R23) -> 0 | V23: =T23-U23 -> 0 | W23: =S23+T23 -> 0
A24: =+A23+1 -> 14 | S24: =G24+I24+K24+M24+O24+Q24 -> 0 | T24: =H24+J24+L24+N24+P24+R24 -> 0 | U24: =IF(H24>2,2,H24)+IF(J24>2,2,J24)+IF(L24>2,2,L24)+IF(N24>2,2,N24)+IF(P24>2,2,P24)+IF(R24>2,2,R24) -> 0 | V24: =T24-U24 -> 0 | W24: =S24+T24 -> 0
A25: =+A24+1 -> 15 | S25: =G25+I25+K25+M25+O25+Q25 -> 0 | T25: =H25+J25+L25+N25+P25+R25 -> 0 | U25: =IF(H25>2,2,H25)+IF(J25>2,2,J25)+IF(L25>2,2,L25)+IF(N25>2,2,N25)+IF(P25>2,2,P25)+IF(R25>2,2,R25) -> 0 | V25: =T25-U25 -> 0 | W25: =S25+T25 -> 0
A26: =+A25+1 -> 16 | S26: =G26+I26+K26+M26+O26+Q26 -> 0 | T26: =H26+J26+L26+N26+P26+R26 -> 0 | U26: =IF(H26>2,2,H26)+IF(J26>2,2,J26)+IF(L26>2,2,L26)+IF(N26>2,2,N26)+IF(P26>2,2,P26)+IF(R26>2,2,R26) -> 0 | V26: =T26-U26 -> 0 | W26: =S26+T26 -> 0
A27: =+A26+1 -> 17 | S27: =G27+I27+K27+M27+O27+Q27 -> 0 | T27: =H27+J27+L27+N27+P27+R27 -> 0 | U27: =IF(H27>2,2,H27)+IF(J27>2,2,J27)+IF(L27>2,2,L27)+IF(N27>2,2,N27)+IF(P27>2,2,P27)+IF(R27>2,2,R27) -> 0 | V27: =T27-U27 -> 0 | W27: =S27+T27 -> 0
A28: =+A27+1 -> 18 | S28: =G28+I28+K28+M28+O28+Q28 -> 0 | T28: =H28+J28+L28+N28+P28+R28 -> 0 | U28: =IF(H28>2,2,H28)+IF(J28>2,2,J28)+IF(L28>2,2,L28)+IF(N28>2,2,N28)+IF(P28>2,2,P28)+IF(R28>2,2,R28) -> 0 | V28: =T28-U28 -> 0 | W28: =S28+T28 -> 0
... A41: =+A40+1 -> 31 | S41: =G41+I41+K41+M41+O41+Q41 -> 0 | T41: =H41+J41+L41+N41+P41+R41 -> 0 | U41: =IF(H41>2,2,H41)+IF(J41>2,2,J41)+IF(L41>2,2,L41)+IF(N41>2,2,N41)+IF(P41>2,2,P41)+IF(R41>2,2,R41) -> 0 | V41: =T41-U41 -> 0 | W41: =S41+T41 -> 0
E42: Total de Horas por dia | G42: =SUM(G11:H41) -> 51 | I42: =SUM(I11:J41) -> 51 | K42: =SUM(K11:L41) -> 51 | M42: =SUM(M11:N41) -> 51 | O42: =SUM(O11:P41) -> 51 | Q42: =SUM(Q11:R41) -> 33 | S42: =SUM(S11:S41) -> 288 | T42: =SUM(T11:T41) -> 0 | U42: =SUM(U11:U41) -> 0 | V42: =SUM(V11:V41) -> 0 | W42: =SUM(W11:W41) -> 288
E43: Numero de personas | G43: =IF(SUM(G11:H41)=0,"0",COUNT(G11:G41)-COUNTIF(G11:G41,0)) -> 6 | I43: =IF(SUM(I11:J41)=0,"0",COUNT(I11:I41)-COUNTIF(I11:I41,0)) -> 6 | K43: =IF(SUM(K11:L41)=0,"0",COUNT(K11:K41)-COUNTIF(K11:K41,0)) -> 6 | M43: =IF(SUM(M11:N41)=0,"0",COUNT(M11:M41)-COUNTIF(M11:M41,0)) -> 6 | O43: =IF(SUM(O11:P41)=0,"0",COUNT(O11:O41)-COUNTIF(O11:O41,0)) -> 6 | Q43: =IF(SUM(Q11:R41)=0,"0",COUNT(Q11:Q41)-COUNTIF(Q11:Q41,0)) -> 6
B44: LEYENDA:
B46: DESCANSO MEDICO | M46: Revisado | U46: Aprobado
B47: RETIRADOS
B48: FALTA
B49: PERMISO
B50: FERIADO
B51: TURNO NOCHE
B52: TRABAJO EN TECHO
B53: INGRESO A OBRA
B54: PAGO DE HORAS ACUMULADAS | I54: .
B55: DESCANSO PATERNIDAD | I55: .

Sheet Hoja1

Sheet TAREO ACTIVIDADES TOTAL
B2: RESUMEN DE ACTIVIDADES
B3: CLIENTE | C3: INVERSIONES SAURIS SAC
B4: PERIODO | C4: =+'TAREO SEMANAL'!F4 -> 2
B5: ITEM | C5: ACTIVIDAD | D5: PARTIDA DE CONTROL | E5: TOTAL DE SEMANA
B7: 1 | C7: Trabajos provisionales almacen | D7: Obras provosionales | E7: =SUMIF('TAREO LUNES'!$C$7:$C$76,'TAREO ACTIVIDADES TOTAL'!C7,'TAREO LUNES'!$E$7:$E$76)+SUMIF('TAREO MARTES'!$C$7:$C$76,'TAREO ACTIVIDADES TOTAL'!C7,'TAREO MARTES'!$E$7:$E$76)+SUMIF('TAREO MIERCOLES'!$C$7:$C$76,'TAREO ACTIVIDADES TOTAL'!C7,'TAREO MIERCOLES'!$E$7:$E$76)+SUMIF('TAREO JUEVES'!$C$7:$C$76,'TAREO ACTIVIDADES TOTAL'!C7,'TAREO JUEVES'!$E$7:$E$76)+SUMIF('TAREO VIERNES'!$C$7:$C$76,'TAREO ACTIVIDADES TOTAL'!C7,'TAREO VIERNES'!$E$7:$E$56)+SUMIF('TAREO SABADO'!$C$7:$C$76,'TAREO ACTIVIDADES TOTAL'!C7,'TAREO SABADO'!$E$7:$E$56) -> 0
B8: =B7+1 -> 2 | C8: vigia | D8: Seguridad Industrial (EPP y EPC), Patrimonial | E8: =SUMIF('TAREO LUNES'!$C$7:$C$76,'TAREO ACTIVIDADES TOTAL'!C8,'TAREO LUNES'!$E$7:$E$76)+SUMIF('TAREO MARTES'!$C$7:$C$76,'TAREO ACTIVIDADES TOTAL'!C8,'TAREO MARTES'!$E$7:$E$76)+SUMIF('TAREO MIERCOLES'!$C$7:$C$76,'TAREO ACTIVIDADES TOTAL'!C8,'TAREO MIERCOLES'!$E$7:$E$76)+SUMIF('TAREO JUEVES'!$C$7:$C$76,'TAREO ACTIVIDADES TOTAL'!C8,'TAREO JUEVES'!$E$7:$E$76)+SUMIF('TAREO VIERNES'!$C$7:$C$76,'TAREO ACTIVIDADES TOTAL'!C8,'TAREO VIERNES'!$E$7:$E$56)+SUMIF('TAREO SABADO'!$C$7:$C$76,'TAREO ACTIVIDADES TOTAL'!C8,'TAREO SABADO'!$E$7:$E$56) -> 42.5
B9: =B8+1 -> 3 | C9: monitor | D9: Seguridad Industrial (EPP y EPC), Patrimonial | E9: =SUMIF('TAREO LUNES'!$C$7:$C$76,'TAREO ACTIVIDADES TOTAL'!C9,'TAREO LUNES'!$E$7:$E$76)+SUMIF('TAREO MARTES'!$C$7:$C$76,'TAREO ACTIVIDADES TOTAL'!C9,'TAREO MARTES'!$E$7:$E$76)+SUMIF('TAREO MIERCOLES'!$C$7:$C$76,'TAREO ACTIVIDADES TOTAL'!C9,'TAREO MIERCOLES'!$E$7:$E$76)+SUMIF('TAREO JUEVES'!$C$7:$C$76,'TAREO ACTIVIDADES TOTAL'!C9,'TAREO JUEVES'!$E$7:$E$76)+SUMIF('TAREO VIERNES'!$C$7:$C$76,'TAREO ACTIVIDADES TOTAL'!C9,'TAREO VIERNES'!$E$7:$E$56)+SUMIF('TAREO SABADO'!$C$7:$C$76,'TAREO ACTIVIDADES TOTAL'!C9,'TAREO SABADO'!$E$7:$E$56) -> 39.5
B10: =B9+1 -> 4 | C10: Limpieza de obra | D10: Varios - Obras Provisionales | E10: =SUMIF('TAREO LUNES'!$C$7:$C$76,'TAREO ACTIVIDADES TOTAL'!C10,'TAREO LUNES'!$E$7:$E$76)+SUMIF('TAREO MARTES'!$C$7:$C$76,'TAREO ACTIVIDADES TOTAL'!C10,'TAREO MARTES'!$E$7:$E$76)+SUMIF('TAREO MIERCOLES'!$C$7:$C$76,'TAREO ACTIVIDADES TOTAL'!C10,'TAREO MIERCOLES'!$E$7:$E$76)+SUMIF('TAREO JUEVES'!$C$7:$C$76,'TAREO ACTIVIDADES TOTAL'!C10,'TAREO JUEVES'!$E$7:$E$76)+SUMIF('TAREO VIERNES'!$C$7:$C$76,'TAREO ACTIVIDADES TOTAL'!C10,'TAREO VIERNES'!$E$7:$E$56)+SUMIF('TAREO SABADO'!$C$7:$C$76,'TAREO ACTIVIDADES TOTAL'!C10,'TAREO SABADO'!$E$7:$E$56) -> 11.5
B11: =B10+1 -> 5 | C11: SNDICATO | D11: Seguridad Industrial (EPP y EPC), Patrimonial | E11: =SUMIF('TAREO LUNES'!$C$7:$C$76,'TAREO ACTIVIDADES TOTAL'!C11,'TAREO LUNES'!$E$7:$E$76)+SUMIF('TAREO MARTES'!$C$7:$C$76,'TAREO ACTIVIDADES TOTAL'!C11,'TAREO MARTES'!$E$7:$E$76)+SUMIF('TAREO MIERCOLES'!$C$7:$C$76,'TAREO ACTIVIDADES TOTAL'!C11,'TAREO MIERCOLES'!$E$7:$E$76)+SUMIF('TAREO JUEVES'!$C$7:$C$76,'TAREO ACTIVIDADES TOTAL'!C11,'TAREO JUEVES'!$E$7:$E$76)+SUMIF('TAREO VIERNES'!$C$7:$C$76,'TAREO ACTIVIDADES TOTAL'!C11,'TAREO VIERNES'!$E$7:$E$56)+SUMIF('TAREO SABADO'!$C$7:$C$76,'TAREO ACTIVIDADES TOTAL'!C11,'TAREO SABADO'!$E$7:$E$56) -> 34
B12: =B11+1 -> 6 | C12: cerco perimetrico provicional | D12: Obras provosionales | E12: =SUMIF('TAREO LUNES'!$C$7:$C$76,'TAREO ACTIVIDADES TOTAL'!C12,'TAREO LUNES'!$E$7:$E$76)+SUMIF('TAREO MARTES'!$C$7:$C$76,'TAREO ACTIVIDADES TOTAL'!C12,'TAREO MARTES'!$E$7:$E$76)+SUMIF('TAREO MIERCOLES'!$C$7:$C$76,'TAREO ACTIVIDADES TOTAL'!C12,'TAREO MIERCOLES'!$E$7:$E$76)+SUMIF('TAREO JUEVES'!$C$7:$C$76,'TAREO ACTIVIDADES TOTAL'!C12,'TAREO JUEVES'!$E$7:$E$76)+SUMIF('TAREO VIERNES'!$C$7:$C$76,'TAREO ACTIVIDADES TOTAL'!C12,'TAREO VIERNES'!$E$7:$E$56)+SUMIF('TAREO SABADO'!$C$7:$C$76,'TAREO ACTIVIDADES TOTAL'!C12,'TAREO SABADO'!$E$7:$E$56) -> 8.5
B13: =B12+1 -> 7 | C13: Trabajos provicionales - oficina staff - Almacen | D13: Caseta para Oficinas, comedor y Cerco perimetrico | E13: =SUMIF('TAREO LUNES'!$C$7:$C$76,'TAREO ACTIVIDADES TOTAL'!C13,'TAREO LUNES'!$E$7:$E$76)+SUMIF('TAREO MARTES'!$C$7:$C$76,'TAREO ACTIVIDADES TOTAL'!C13,'TAREO MARTES'!$E$7:$E$76)+SUMIF('TAREO MIERCOLES'!$C$7:$C$76,'TAREO ACTIVIDADES TOTAL'!C13,'TAREO MIERCOLES'!$E$7:$E$76)+SUMIF('TAREO JUEVES'!$C$7:$C$76,'TAREO ACTIVIDADES TOTAL'!C13,'TAREO JUEVES'!$E$7:$E$76)+SUMIF('TAREO VIERNES'!$C$7:$C$76,'TAREO ACTIVIDADES TOTAL'!C13,'TAREO VIERNES'!$E$7:$E$56)+SUMIF('TAREO SABADO'!$C$7:$C$76,'TAREO ACTIVIDADES TOTAL'!C13,'TAREO SABADO'!$E$7:$E$56) -> 8.5
B14: =B13+1 -> 8 | C14: Trabajos provicionales - baños | D14: Servicios Higienicos para Staff y Obreros | E14: =SUMIF('TAREO LUNES'!$C$7:$C$76,'TAREO ACTIVIDADES TOTAL'!C14,'TAREO LUNES'!$E$7:$E$76)+SUMIF('TAREO MARTES'!$C$7:$C$76,'TAREO ACTIVIDADES TOTAL'!C14,'TAREO MARTES'!$E$7:$E$76)+SUMIF('TAREO MIERCOLES'!$C$7:$C$76,'TAREO ACTIVIDADES TOTAL'!C14,'TAREO MIERCOLES'!$E$7:$E$76)+SUMIF('TAREO JUEVES'!$C$7:$C$76,'TAREO ACTIVIDADES TOTAL'!C14,'TAREO JUEVES'!$E$7:$E$76)+SUMIF('TAREO VIERNES'!$C$7:$C$76,'TAREO ACTIVIDADES TOTAL'!C14,'TAREO VIERNES'!$E$7:$E$56)+SUMIF('TAREO SABADO'!$C$7:$C$76,'TAREO ACTIVIDADES TOTAL'!C14,'TAREO SABADO'!$E$7:$E$56) -> 0
B15: =B14+1 -> 9 | C15: Señalizacion de obra | D15: Seguridad Industrial (EPP y EPC), Patrimonial | E15: =SUMIF('TAREO LUNES'!$C$7:$C$76,'TAREO ACTIVIDADES TOTAL'!C15,'TAREO LUNES'!$E$7:$E$76)+SUMIF('TAREO MARTES'!$C$7:$C$76,'TAREO ACTIVIDADES TOTAL'!C15,'TAREO MARTES'!$E$7:$E$76)+SUMIF('TAREO MIERCOLES'!$C$7:$C$76,'TAREO ACTIVIDADES TOTAL'!C15,'TAREO MIERCOLES'!$E$7:$E$76)+SUMIF('TAREO JUEVES'!$C$7:$C$76,'TAREO ACTIVIDADES TOTAL'!C15,'TAREO JUEVES'!$E$7:$E$76)+SUMIF('TAREO VIERNES'!$C$7:$C$76,'TAREO ACTIVIDADES TOTAL'!C15,'TAREO VIERNES'!$E$7:$E$56)+SUMIF('TAREO SABADO'!$C$7:$C$76,'TAREO ACTIVIDADES TOTAL'!C15,'TAREO SABADO'!$E$7:$E$56) -> 8
B16: =B15+1 -> 10 | C16: Topografia | D16: Topografia | E16: =SUMIF('TAREO LUNES'!$C$7:$C$76,'TAREO ACTIVIDADES TOTAL'!C16,'TAREO LUNES'!$E$7:$E$76)+SUMIF('TAREO MARTES'!$C$7:$C$76,'TAREO ACTIVIDADES TOTAL'!C16,'TAREO MARTES'!$E$7:$E$76)+SUMIF('TAREO MIERCOLES'!$C$7:$C$76,'TAREO ACTIVIDADES TOTAL'!C16,'TAREO MIERCOLES'!$E$7:$E$76)+SUMIF('TAREO JUEVES'!$C$7:$C$76,'TAREO ACTIVIDADES TOTAL'!C16,'TAREO JUEVES'!$E$7:$E$76)+SUMIF('TAREO VIERNES'!$C$7:$C$76,'TAREO ACTIVIDADES TOTAL'!C16,'TAREO VIERNES'!$E$7:$E$56)+SUMIF('TAREO SABADO'!$C$7:$C$76,'TAREO ACTIVIDADES TOTAL'!C16,'TAREO SABADO'!$E$7:$E$56) -> 96
B17: =B16+1 -> 11 | C17: Protecciones colectivas | D17: Seguridad Industrial (EPP y EPC), Patrimonial | E17: =SUMIF('TAREO LUNES'!$C$7:$C$76,'TAREO ACTIVIDADES TOTAL'!C17,'TAREO LUNES'!$E$7:$E$76)+SUMIF('TAREO MARTES'!$C$7:$C$76,'TAREO ACTIVIDADES TOTAL'!C17,'TAREO MARTES'!$E$7:$E$76)+SUMIF('TAREO MIERCOLES'!$C$7:$C$76,'TAREO ACTIVIDADES TOTAL'!C17,'TAREO MIERCOLES'!$E$7:$E$76)+SUMIF('TAREO JUEVES'!$C$7:$C$76,'TAREO ACTIVIDADES TOTAL'!C17,'TAREO JUEVES'!$E$7:$E$76)+SUMIF('TAREO VIERNES'!$C$7:$C$76,'TAREO ACTIVIDADES TOTAL'!C17,'TAREO VIERNES'!$E$7:$E$56)+SUMIF('TAREO SABADO'!$C$7:$C$76,'TAREO ACTIVIDADES TOTAL'!C17,'TAREO SABADO'!$E$7:$E$56) -> 0
B18: =B17+1 -> 12 | C18: Limpieza de vecinos | D18: Varios - Obras Provisionales | E18: =SUMIF('TAREO LUNES'!$C$7:$C$76,'TAREO ACTIVIDADES TOTAL'!C18,'TAREO LUNES'!$E$7:$E$76)+SUMIF('TAREO MARTES'!$C$7:$C$76,'TAREO ACTIVIDADES TOTAL'!C18,'TAREO MARTES'!$E$7:$E$76)+SUMIF('TAREO MIERCOLES'!$C$7:$C$76,'TAREO ACTIVIDADES TOTAL'!C18,'TAREO MIERCOLES'!$E$7:$E$76)+SUMIF('TAREO JUEVES'!$C$7:$C$76,'TAREO ACTIVIDADES TOTAL'!C18,'TAREO JUEVES'!$E$7:$E$76)+SUMIF('TAREO VIERNES'!$C$7:$C$76,'TAREO ACTIVIDADES TOTAL'!C18,'TAREO VIERNES'!$E$7:$E$56)+SUMIF('TAREO SABADO'!$C$7:$C$76,'TAREO ACTIVIDADES TOTAL'!C18,'TAREO SABADO'!$E$7:$E$56) -> 0
B19: =B18+1 -> 13 | C19: Traslado de materiales de Almacen | D19: Traslado Vertical y Horizontal | E19: =SUMIF('TAREO LUNES'!$C$7:$C$76,'TAREO ACTIVIDADES TOTAL'!C19,'TAREO LUNES'!$E$7:$E$76)+SUMIF('TAREO MARTES'!$C$7:$C$76,'TAREO ACTIVIDADES TOTAL'!C19,'TAREO MARTES'!$E$7:$E$76)+SUMIF('TAREO MIERCOLES'!$C$7:$C$76,'TAREO ACTIVIDADES TOTAL'!C19,'TAREO MIERCOLES'!$E$7:$E$76)+SUMIF('TAREO JUEVES'!$C$7:$C$76,'TAREO ACTIVIDADES TOTAL'!C19,'TAREO JUEVES'!$E$7:$E$76)+SUMIF('TAREO VIERNES'!$C$7:$C$76,'TAREO ACTIVIDADES TOTAL'!C19,'TAREO VIERNES'!$E$7:$E$56)+SUMIF('TAREO SABADO'!$C$7:$C$76,'TAREO ACTIVIDADES TOTAL'!C19,'TAREO SABADO'!$E$7:$E$56) -> 0
... B75: =B74+1 -> 69 | C75: Colocacion de señaletias | D75: Varios - Arquitectura | E75: =SUMIF('TAREO LUNES'!$C$7:$C$76,'TAREO ACTIVIDADES TOTAL'!C75,'TAREO LUNES'!$E$7:$E$76)+SUMIF('TAREO MARTES'!$C$7:$C$76,'TAREO ACTIVIDADES TOTAL'!C75,'TAREO MARTES'!$E$7:$E$76)+SUMIF('TAREO MIERCOLES'!$C$7:$C$76,'TAREO ACTIVIDADES TOTAL'!C75,'TAREO MIERCOLES'!$E$7:$E$76)+SUMIF('TAREO JUEVES'!$C$7:$C$76,'TAREO ACTIVIDADES TOTAL'!C75,'TAREO JUEVES'!$E$7:$E$76)+SUMIF('TAREO VIERNES'!$C$7:$C$76,'TAREO ACTIVIDADES TOTAL'!C75,'TAREO VIERNES'!$E$7:$E$56)+SUMIF('TAREO SABADO'!$C$7:$C$76,'TAREO ACTIVIDADES TOTAL'!C75,'TAREO SABADO'!$E$7:$E$56) -> 0
B76: =B75+1 -> 70 | E76: =SUMIF('TAREO LUNES'!$C$7:$C$76,'TAREO ACTIVIDADES TOTAL'!C76,'TAREO LUNES'!$E$7:$E$76)+SUMIF('TAREO MARTES'!$C$7:$C$76,'TAREO ACTIVIDADES TOTAL'!C76,'TAREO MARTES'!$E$7:$E$76)+SUMIF('TAREO MIERCOLES'!$C$7:$C$76,'TAREO ACTIVIDADES TOTAL'!C76,'TAREO MIERCOLES'!$E$7:$E$76)+SUMIF('TAREO JUEVES'!$C$7:$C$76,'TAREO ACTIVIDADES TOTAL'!C76,'TAREO JUEVES'!$E$7:$E$76)+SUMIF('TAREO VIERNES'!$C$7:$C$76,'TAREO ACTIVIDADES TOTAL'!C76,'TAREO VIERNES'!$E$7:$E$56)+SUMIF('TAREO SABADO'!$C$7:$C$76,'TAREO ACTIVIDADES TOTAL'!C76,'TAREO SABADO'!$E$7:$E$56) -> 0
B77: TOTAL DE HORAS POR ACTIVIDAD | D77: =+'TAREO LUNES'!AK77+'TAREO MARTES'!AK77+'TAREO MIERCOLES'!AK77+'TAREO JUEVES'!AN77+'TAREO VIERNES'!AK77+'TAREO SABADO'!AK77 -> 160.5 | E77: =SUM(E7:E76) -> 294

Sheet TAREO LUNES
B2: TAREO DE DIARIO OBRERO POR ACTIVIDAD
B3: CLIENTE | C3: INVERSIONES SAURIS SAC | M3: FECHA: | O3: =+'TAREO SEMANAL'!H4 -> 45711 | AQ3: OBSERVACIONES
B5: ITEM | C5: ACTIVIDAD | D5: PARTIDA DE CONTROL | E5: TOTAL DE HORAS POR ACTIVIDAD | F5: =+CONCATENATE('TAREO SEMANAL'!$B11," ",'TAREO SEMANAL'!$C11) -> PEREZ GALLEGOS JORGE ANDRES | G5: =+CONCATENATE('TAREO SEMANAL'!$B12," ",'TAREO SEMANAL'!$C12) -> SANCHEZ BUSTAMANTE DAVID GONZALO | H5: =+CONCATENATE('TAREO SEMANAL'!$B13," ",'TAREO SEMANAL'!$C13) -> SANDOVAL CONDORI VICTOR ANGEL | I5: =+CONCATENATE('TAREO SEMANAL'!$B14," ",'TAREO SEMANAL'!$C14) -> ELME MORAN JOHN JORGE | J5: =+CONCATENATE('TAREO SEMANAL'!$B15," ",'TAREO SEMANAL'!$C15) -> ELME CURIPACO DIETRICH RODRIGO | K5: =+CONCATENATE('TAREO SEMANAL'!$B16," ",'TAREO SEMANAL'!$C16) -> CHUQUILIN ANGULO OSCAR JUNIOR | L5: =+CONCATENATE('TAREO SEMANAL'!$B17," ",'TAREO SEMANAL'!$C17) | M5: =+CONCATENATE('TAREO SEMANAL'!$B18," ",'TAREO SEMANAL'!$C18) | N5: =+CONCATENATE('TAREO SEMANAL'!$B19," ",'TAREO SEMANAL'!$C19) | O5: =+CONCATENATE('TAREO SEMANAL'!$B20," ",'TAREO SEMANAL'!$C20) | P5: =+CONCATENATE('TAREO SEMANAL'!$B21," ",'TAREO SEMANAL'!$C21) | Q5: =+CONCATENATE('TAREO SEMANAL'!$B22," ",'TAREO SEMANAL'!$C22) | R5: =+CONCATENATE('TAREO SEMANAL'!$B23," ",'TAREO SEMANAL'!$C23) | S5: =+CONCATENATE('TAREO SEMANAL'!$B24," ",'TAREO SEMANAL'!$C24) | T5: =+CONCATENATE('TAREO SEMANAL'!$B25," ",'TAREO SEMANAL'!$C25) | U5: =+CONCATENATE('TAREO SEMANAL'!$B26," ",'TAREO SEMANAL'!$C26) | V5: =+CONCATENATE('TAREO SEMANAL'!$B27," ",'TAREO SEMANAL'!$C27) | W5: =+CONCATENATE('TAREO SEMANAL'!$B28," ",'TAREO SEMANAL'!$C28) | X5: =+CONCATENATE('TAREO SEMANAL'!$B29," ",'TAREO SEMANAL'!$C29) | Y5: =+CONCATENATE('TAREO SEMANAL'!$B30," ",'TAREO SEMANAL'!$C30) | Z5: =+CONCATENATE('TAREO SEMANAL'!$B31," ",'TAREO SEMANAL'!$C31) | AA5: =+CONCATENATE('TAREO SEMANAL'!$B32," ",'TAREO SEMANAL'!$C32) | AB5: =+CONCATENATE('TAREO SEMANAL'!$B33," ",'TAREO SEMANAL'!$C33) | AC5: =+CONCATENATE('TAREO SEMANAL'!$B34," ",'TAREO SEMANAL'!$C34) | AD5: =+CONCATENATE('TAREO SEMANAL'!$B35," ",'TAREO SEMANAL'!$C35) | AE5: =+CONCATENATE('TAREO SEMANAL'!$B36," ",'TAREO SEMANAL'!$C36) | AF5: =+CONCATENATE('TAREO SEMANAL'!$B37," ",'TAREO SEMANAL'!$C37) | AG5: =+CONCATENATE('TAREO SEMANAL'!$B38," ",'TAREO SEMANAL'!$C38) | AH5: =+CONCATENATE('TAREO SEMANAL'!$B39," ",'TAREO SEMANAL'!$C39) | AI5: =+CONCATENATE('TAREO SEMANAL'!$B40," ",'TAREO SEMANAL'!$C40) | AJ5: =+CONCATENATE('TAREO SEMANAL'!$B41," ",'TAREO SEMANAL'!$C41)
F6: 1 | G6: =+F6+1 -> 2 | H6: =+G6+1 -> 3 | I6: =+H6+1 -> 4 | J6: =+I6+1 -> 5 | K6: =+J6+1 -> 6 | L6: =+K6+1 -> 7 | M6: =+L6+1 -> 8 | N6: =+M6+1 -> 9 | O6: =+N6+1 -> 10 | P6: 11 | Q6: 12 | R6: =+Q6+1 -> 13 | S6: 14 | T6: 15 | U6: =+T6+1 -> 16 | V6: =+U6+1 -> 17 | W6: 18 | X6: =+W6+1 -> 19 | Y6: =+X6+1 -> 20 | Z6: =+Y6+1 -> 21 | AA6: 22 | AB6: =+AA6+1 -> 23 | AC6: =+AB6+1 -> 24 | AD6: =+AC6+1 -> 25 | AE6: 26 | AF6: =+AE6+1 -> 27 | AG6: =+AF6+1 -> 28 | AH6: =+AG6+1 -> 29 | AI6: =+AH6+1 -> 30 | AJ6: =+AI6+1 -> 31
B7: 1 | C7: =+'TAREO ACTIVIDADES TOTAL'!C7 -> Trabajos provisionales almacen | D7: =+'TAREO ACTIVIDADES TOTAL'!D7 -> Obras provosionales | E7: =SUM(F7:AJ7) -> 0
B8: =B7+1 -> 2 | C8: vigia exterior | D8: Seguridad Industrial (EPP y EPC), Patrimonial | E8: =SUM(F8:AJ8) -> 8.5 | F8: 8.5
B9: =B8+1 -> 3 | C9: =+'TAREO ACTIVIDADES TOTAL'!C9 -> monitor | D9: =+'TAREO ACTIVIDADES TOTAL'!D9 -> Seguridad Industrial (EPP y EPC), Patrimonial | E9: =SUM(F9:AJ9) -> 8.5 | K9: 8.5
B10: =B9+1 -> 4 | C10: =+'TAREO ACTIVIDADES TOTAL'!C10 -> Limpieza de obra | D10: =+'TAREO ACTIVIDADES TOTAL'!D10 -> Varios - Obras Provisionales | E10: =SUM(F10:AJ10) -> 0
B11: =B10+1 -> 5 | C11: =+'TAREO ACTIVIDADES TOTAL'!C11 -> SNDICATO | D11: =+'TAREO ACTIVIDADES TOTAL'!D11 -> Seguridad Industrial (EPP y EPC), Patrimonial | E11: =SUM(F11:AJ11) -> 8.5 | H11: 8.5
B12: =B11+1 -> 6 | C12: =+'TAREO ACTIVIDADES TOTAL'!C12 -> cerco perimetrico provicional | D12: =+'TAREO ACTIVIDADES TOTAL'!D12 -> Obras provosionales | E12: =SUM(F12:AJ12) -> 8.5 | G12: 8.5
B13: =B12+1 -> 7 | C13: =+'TAREO ACTIVIDADES TOTAL'!C13 -> Trabajos provicionales - oficina staff - Almacen | D13: =+'TAREO ACTIVIDADES TOTAL'!D13 -> Caseta para Oficinas, comedor y Cerco perimetrico | E13: =SUM(F13:AJ13) -> 0
B14: =B13+1 -> 8 | C14: =+'TAREO ACTIVIDADES TOTAL'!C14 -> Trabajos provicionales - baños | D14: =+'TAREO ACTIVIDADES TOTAL'!D14 -> Servicios Higienicos para Staff y Obreros | E14: =SUM(F14:AJ14) -> 0
B15: =B14+1 -> 9 | C15: =+'TAREO ACTIVIDADES TOTAL'!C15 -> Señalizacion de obra | D15: =+'TAREO ACTIVIDADES TOTAL'!D15 -> Seguridad Industrial (EPP y EPC), Patrimonial | E15: =SUM(F15:AJ15) -> 0
B16: =B15+1 -> 10 | C16: =+'TAREO ACTIVIDADES TOTAL'!C16 -> Topografia | D16: =+'TAREO ACTIVIDADES TOTAL'!D16 -> Topografia | E16: =SUM(F16:AJ16) -> 17 | I16: 8.5 | J16: 8.5
B17: =B16+1 -> 11 | C17: =+'TAREO ACTIVIDADES TOTAL'!C17 -> Protecciones colectivas | D17: =+'TAREO ACTIVIDADES TOTAL'!D17 -> Seguridad Industrial (EPP y EPC), Patrimonial | E17: =SUM(F17:AJ17) -> 0
B18: =B17+1 -> 12 | C18: =+'TAREO ACTIVIDADES TOTAL'!C18 -> Limpieza de vecinos | D18: =+'TAREO ACTIVIDADES TOTAL'!D18 -> Varios - Obras Provisionales | E18: =SUM(F18:AJ18) -> 0
B19: =B18+1 -> 13 | C19: =+'TAREO ACTIVIDADES TOTAL'!C19 -> Traslado de materiales de Almacen | D19: =+'TAREO ACTIVIDADES TOTAL'!D19 -> Traslado Vertical y Horizontal | E19: =SUM(F19:AJ19) -> 0
B20: =B19+1 -> 14 | C20: =+'TAREO ACTIVIDADES TOTAL'!C20 -> umedecer terreno | D20: =+'TAREO ACTIVIDADES TOTAL'!D20 -> movimientos de tierra | E20: =SUM(F20:AJ20) -> 0
B21: =B20+1 -> 15 | C21: =+'TAREO ACTIVIDADES TOTAL'!C21 -> Acarreo Horizontal | D21: =+'TAREO ACTIVIDADES TOTAL'!D21 -> Traslado Vertical y Horizontal | E21: =SUM(F21:AJ21) -> 0
B22: =B21+1 -> 16 | C22: =+'TAREO ACTIVIDADES TOTAL'!C22 -> Acarreo Vertical | D22: =+'TAREO ACTIVIDADES TOTAL'!D22 -> Traslado Vertical y Horizontal | E22: =SUM(F22:AJ22) -> 0
B23: =B22+1 -> 17 | C23: =+'TAREO ACTIVIDADES TOTAL'!C23 -> Forjado de escaleras en sotano | D23: =+'TAREO ACTIVIDADES TOTAL'!D23 -> Contrapiso y Acabados en Cemento | E23: =SUM(F23:AJ23) -> 0
B24: =B23+1 -> 18 | C24: =+'TAREO ACTIVIDADES TOTAL'!C24 -> Bimastil | D24: =+'TAREO ACTIVIDADES TOTAL'!D24 -> Marmol, Granito, Cuarzo | E24: =SUM(F24:AJ24) -> 0
B25: =B24+1 -> 19 | C25: =+'TAREO ACTIVIDADES TOTAL'!C25 -> colocacion bordes pvc en escaleras | D25: =+'TAREO ACTIVIDADES TOTAL'!D25 -> varios arquitectura | E25: =SUM(F25:AJ25) -> 0
B26: =B25+1 -> 20 | C26: =+'TAREO ACTIVIDADES TOTAL'!C26 -> Asentado de ladrillo remates sotanos | D26: =+'TAREO ACTIVIDADES TOTAL'!D26 -> Muros de Albañileria | E26: =SUM(F26:AJ26) -> 0
B27: =B26+1 -> 21 | C27: =+'TAREO ACTIVIDADES TOTAL'!C27 -> Copado resanes y limpieza de vigas y columnas de fachada | D27: =+'TAREO ACTIVIDADES TOTAL'!D27 -> Pintura y recubrimiento | E27: =SUM(F27:AJ27) -> 0
B28: =B27+1 -> 22 | C28: =+'TAREO ACTIVIDADES TOTAL'!C28 -> Resane en sotanos pisos y muros | D28: =+'TAREO ACTIVIDADES TOTAL'!D28 -> Tarrajeo, Revoques y Enlucido | E28: =SUM(F28:AJ28) -> 0
... B31: =B30+1 -> 25 | C31: =+'TAREO ACTIVIDADES TOTAL'!C31 -> resanes en casa vecinas | D31: =+'TAREO ACTIVIDADES TOTAL'!D31 -> varios arquitectura | E31: =SUM(F31:AJ31) -> 0
B32: =B31+1 -> 26 | C32: =+'TAREO ACTIVIDADES TOTAL'!C32 -> resanes piso 16 | D32: =+'TAREO ACTIVIDADES TOTAL'!D32 -> Tarrajeo, Revoques y Enlucido | E32: =SUM(F32:AJ32) -> 0 | Q32: .
B33: =B32+1 -> 27 | C33: =+'TAREO ACTIVIDADES TOTAL'!C33 -> Limpieza en zona de piscina | D33: =+'TAREO ACTIVIDADES TOTAL'!D33 -> Seguridad Industrial (EPP y EPC), Patrimonial | E33: =SUM(F33:AJ33) -> 0
B34: =B33+1 -> 28 | C34: =+'TAREO ACTIVIDADES TOTAL'!C34 -> Solaqueo de pasosy contrapasos de escalera de evacuacion | D34: =+'TAREO ACTIVIDADES TOTAL'!D34 -> Contrapiso y Acabados en Cemento | E34: =SUM(F34:AJ34) -> 0
B35: =B34+1 -> 29 | C35: =+'TAREO ACTIVIDADES TOTAL'!C35 -> armado y desarmado de andamios | D35: =+'TAREO ACTIVIDADES TOTAL'!D35 -> Pintura y recubrimiento | E35: =SUM(F35:AJ35) -> 0
B36: =B35+1 -> 30 | C36: =+'TAREO ACTIVIDADES TOTAL'!C36 -> Limpieza y acarreo de escombros de departamentos | D36: =+'TAREO ACTIVIDADES TOTAL'!D36 -> Seguridad Industrial (EPP y EPC), Patrimonial | E36: =SUM(F36:AJ36) -> 0
B37: =B36+1 -> 31 | C37: =+'TAREO ACTIVIDADES TOTAL'!C37 -> Eliminacion de desmonte y escombros | D37: =+'TAREO ACTIVIDADES TOTAL'!D37 -> Eliminación de basura y desmonte con cajas ecologicas | E37: =SUM(F37:AJ37) -> 0
B38: =B37+1 -> 32 | C38: =+'TAREO ACTIVIDADES TOTAL'!C38 -> Limpieza de rebabas de piso para enchape | D38: =+'TAREO ACTIVIDADES TOTAL'!D38 -> Tarrajeo, Revoques y Enlucido | E38: =SUM(F38:AJ38) -> 0
B39: =B38+1 -> 33 | C39: =+'TAREO ACTIVIDADES TOTAL'!C39 -> Picado y forjado de canaletas para mamparas y duchas | D39: =+'TAREO ACTIVIDADES TOTAL'!D39 -> Contrapiso y Acabados en Cemento | E39: =SUM(F39:AJ39) -> 0
B40: =B39+1 -> 34 | C40: =+'TAREO ACTIVIDADES TOTAL'!C40 -> Correccion de centros dicroicos | D40: =+'TAREO ACTIVIDADES TOTAL'!D40 -> Tarrajeo, Revoques y Enlucido | E40: =SUM(F40:AJ40) -> 0
B41: =B40+1 -> 35 | C41: =+'TAREO ACTIVIDADES TOTAL'!C41 -> fragua en enchapesy sellado fachada | D41: =+'TAREO ACTIVIDADES TOTAL'!D41 -> Pisos de enchape ceramico y porcelanato | E41: =SUM(F41:AJ41) -> 0
B42: =B41+1 -> 36 | C42: =+'TAREO ACTIVIDADES TOTAL'!C42 -> Remate de pintura en departamentos | D42: =+'TAREO ACTIVIDADES TOTAL'!D42 -> Pintura y recubrimiento | E42: =SUM(F42:AJ42) -> 0
B43: =B42+1 -> 37 | C43: =+'TAREO ACTIVIDADES TOTAL'!C43 -> Remate de pintura en areas comunes | D43: =+'TAREO ACTIVIDADES TOTAL'!D43 -> Pintura y recubrimiento | E43: =SUM(F43:AJ43) -> 0
B44: =B43+1 -> 38 | C44: =+'TAREO ACTIVIDADES TOTAL'!C44 -> Instalacion de drywall en departamentos | D44: =+'TAREO ACTIVIDADES TOTAL'!D44 -> Drywall y Falso Cielo Raso | E44: =SUM(F44:AJ44) -> 0
...

Sheet TAREO MARTES
B2: TAREO DE DIARIO OBRERO POR ACTIVIDAD
B3: CLIENTE | C3: INVERSIONES SAURIS SAC | N3: FECHA: | O3: =+'TAREO LUNES'!O3:AP3+1 -> 45712 | AQ3: OBSERVACIONES
B5: ITEM | C5: TRABAJADOR | D5: PARTIDA DE CONTROL | E5: TOTAL DE HORAS POR ACTIVIDAD | F5: =+CONCATENATE('TAREO SEMANAL'!$B11," ",'TAREO SEMANAL'!$C11) -> PEREZ GALLEGOS JORGE ANDRES | G5: =+CONCATENATE('TAREO SEMANAL'!$B12," ",'TAREO SEMANAL'!$C12) -> SANCHEZ BUSTAMANTE DAVID GONZALO | H5: =+CONCATENATE('TAREO SEMANAL'!$B13," ",'TAREO SEMANAL'!$C13) -> SANDOVAL CONDORI VICTOR ANGEL | I5: =+CONCATENATE('TAREO SEMANAL'!$B14," ",'TAREO SEMANAL'!$C14) -> ELME MORAN JOHN JORGE | J5: =+CONCATENATE('TAREO SEMANAL'!$B15," ",'TAREO SEMANAL'!$C15) -> ELME CURIPACO DIETRICH RODRIGO | K5: =+CONCATENATE('TAREO SEMANAL'!$B16," ",'TAREO SEMANAL'!$C16) -> CHUQUILIN ANGULO OSCAR JUNIOR | L5: =+CONCATENATE('TAREO SEMANAL'!$B17," ",'TAREO SEMANAL'!$C17) | M5: =+CONCATENATE('TAREO SEMANAL'!$B18," ",'TAREO SEMANAL'!$C18) | N5: =+CONCATENATE('TAREO SEMANAL'!$B19," ",'TAREO SEMANAL'!$C19) | O5: =+CONCATENATE('TAREO SEMANAL'!$B20," ",'TAREO SEMANAL'!$C20) | P5: =+CONCATENATE('TAREO SEMANAL'!$B21," ",'TAREO SEMANAL'!$C21) | Q5: =+CONCATENATE('TAREO SEMANAL'!$B22," ",'TAREO SEMANAL'!$C22) | R5: =+CONCATENATE('TAREO SEMANAL'!$B23," ",'TAREO SEMANAL'!$C23) | S5: =+CONCATENATE('TAREO SEMANAL'!$B24," ",'TAREO SEMANAL'!$C24) | T5: =+CONCATENATE('TAREO SEMANAL'!$B25," ",'TAREO SEMANAL'!$C25) | U5: =+CONCATENATE('TAREO SEMANAL'!$B26," ",'TAREO SEMANAL'!$C26) | V5: =+CONCATENATE('TAREO SEMANAL'!$B27," ",'TAREO SEMANAL'!$C27) | W5: =+CONCATENATE('TAREO SEMANAL'!$B28," ",'TAREO SEMANAL'!$C28) | X5: =+CONCATENATE('TAREO SEMANAL'!$B29," ",'TAREO SEMANAL'!$C29) | Y5: =+CONCATENATE('TAREO SEMANAL'!$B30," ",'TAREO SEMANAL'!$C30) | Z5: =+CONCATENATE('TAREO SEMANAL'!$B31," ",'TAREO SEMANAL'!$C31) | AA5: =+CONCATENATE('TAREO SEMANAL'!$B32," ",'TAREO SEMANAL'!$C32) | AB5: =+CONCATENATE('TAREO SEMANAL'!$B33," ",'TAREO SEMANAL'!$C33) | AC5: =+CONCATENATE('TAREO SEMANAL'!$B34," ",'TAREO SEMANAL'!$C34) | AE5: =+CONCATENATE('TAREO SEMANAL'!$B36," ",'TAREO SEMANAL'!$C36) | AF5: =+CONCATENATE('TAREO SEMANAL'!$B37," ",'TAREO SEMANAL'!$C37) | AG5: =+CONCATENATE('TAREO SEMANAL'!$B38," ",'TAREO SEMANAL'!$C38) | AH5: =+CONCATENATE('TAREO SEMANAL'!$B39," ",'TAREO SEMANAL'!$C39) | AI5: =+CONCATENATE('TAREO SEMANAL'!$B40," ",'TAREO SEMANAL'!$C40) | AJ5: =+CONCATENATE('TAREO SEMANAL'!$B41," ",'TAREO SEMANAL'!$C41)
C6: ACTIVIDAD | F6: 1 | G6: =+F6+1 -> 2 | H6: =+G6+1 -> 3 | I6: =+H6+1 -> 4 | J6: =+I6+1 -> 5 | K6: =+J6+1 -> 6 | L6: =+K6+1 -> 7 | M6: =+L6+1 -> 8 | N6: =+M6+1 -> 9 | O6: =+N6+1 -> 10 | P6: 11 | Q6: =+P6+1 -> 12 | R6: =+Q6+1 -> 13 | S6: 14 | T6: =+S6+1 -> 15 | U6: =+T6+1 -> 16 | V6: 17 | W6: 18 | X6: 19 | Y6: 20 | Z6: 21 | AA6: 22 | AB6: 23 | AC6: 24 | AD6: 25 | AE6: 26 | AF6: 27 | AG6: 28 | AH6: 29 | AI6: 30 | AJ6: 38
B7: 1 | C7: =+'TAREO ACTIVIDADES TOTAL'!C7 -> Trabajos provisionales almacen | D7: =+'TAREO ACTIVIDADES TOTAL'!D7 -> Obras provosionales | E7: =SUM(F7:AJ7) -> 0
B8: =B7+1 -> 2 | C8: =+'TAREO ACTIVIDADES TOTAL'!C8 -> vigia | D8: =+'TAREO ACTIVIDADES TOTAL'!D8 -> Seguridad Industrial (EPP y EPC), Patrimonial | E8: =SUM(F8:AJ8) -> 8.5 | F8: 8.5
B9: =B8+1 -> 3 | C9: =+'TAREO ACTIVIDADES TOTAL'!C9 -> monitor | D9: =+'TAREO ACTIVIDADES TOTAL'!D9 -> Seguridad Industrial (EPP y EPC), Patrimonial | E9: =SUM(F9:AJ9) -> 8.5 | K9: 8.5
B10: =B9+1 -> 4 | C10: =+'TAREO ACTIVIDADES TOTAL'!C10 -> Limpieza de obra | D10: =+'TAREO ACTIVIDADES TOTAL'!D10 -> Varios - Obras Provisionales | E10: =SUM(F10:AJ10) -> 8.5 | H10: 8.5
B11: =B10+1 -> 5 | C11: =+'TAREO ACTIVIDADES TOTAL'!C11 -> SNDICATO | D11: =+'TAREO ACTIVIDADES TOTAL'!D11 -> Seguridad Industrial (EPP y EPC), Patrimonial | E11: =SUM(F11:AJ11) -> 0
B12: =B11+1 -> 6 | C12: =+'TAREO ACTIVIDADES TOTAL'!C12 -> cerco perimetrico provicional | D12: =+'TAREO ACTIVIDADES TOTAL'!D12 -> Obras provosionales | E12: =SUM(F12:AJ12) -> 0 | AK12: picado
B13: =B12+1 -> 7 | C13: =+'TAREO ACTIVIDADES TOTAL'!C13 -> Trabajos provicionales - oficina staff - Almacen | D13: =+'TAREO ACTIVIDADES TOTAL'!D13 -> Caseta para Oficinas, comedor y Cerco perimetrico | E13: =SUM(F13:AJ13) -> 8.5 | G13: 8.5
B14: =B13+1 -> 8 | C14: =+'TAREO ACTIVIDADES TOTAL'!C14 -> Trabajos provicionales - baños | D14: =+'TAREO ACTIVIDADES TOTAL'!D14 -> Servicios Higienicos para Staff y Obreros | E14: =SUM(F14:AJ14) -> 0
B15: =B14+1 -> 9 | C15: =+'TAREO ACTIVIDADES TOTAL'!C15 -> Señalizacion de obra | D15: =+'TAREO ACTIVIDADES TOTAL'!D15 -> Seguridad Industrial (EPP y EPC), Patrimonial | E15: =SUM(F15:AJ15) -> 0
B16: =B15+1 -> 10 | C16: =+'TAREO ACTIVIDADES TOTAL'!C16 -> Topografia | D16: =+'TAREO ACTIVIDADES TOTAL'!D16 -> Topografia | E16: =SUM(F16:AJ16) -> 17 | I16: 8.5 | J16: 8.5
B17: =B16+1 -> 11 | C17: =+'TAREO ACTIVIDADES TOTAL'!C17 -> Protecciones colectivas | D17: =+'TAREO ACTIVIDADES TOTAL'!D17 -> Seguridad Industrial (EPP y EPC), Patrimonial | E17: =SUM(F17:AJ17) -> 0
B18: =B17+1 -> 12 | C18: =+'TAREO ACTIVIDADES TOTAL'!C18 -> Limpieza de vecinos | D18: =+'TAREO ACTIVIDADES TOTAL'!D18 -> Varios - Obras Provisionales | E18: =SUM(F18:AJ18) -> 0
B19: =B18+1 -> 13 | C19: =+'TAREO ACTIVIDADES TOTAL'!C19 -> Traslado de materiales de Almacen | D19: =+'TAREO ACTIVIDADES TOTAL'!D19 -> Traslado Vertical y Horizontal | E19: =SUM(F19:AJ19) -> 0
B20: =B19+1 -> 14 | C20: =+'TAREO ACTIVIDADES TOTAL'!C20 -> umedecer terreno | D20: =+'TAREO ACTIVIDADES TOTAL'!D20 -> movimientos de tierra | E20: =SUM(F20:AJ20) -> 0
B21: =B20+1 -> 15 | C21: =+'TAREO ACTIVIDADES TOTAL'!C21 -> Acarreo Horizontal | D21: =+'TAREO ACTIVIDADES TOTAL'!D21 -> Traslado Vertical y Horizontal | E21: =SUM(F21:AJ21) -> 0
B22: =B21+1 -> 16 | C22: =+'TAREO ACTIVIDADES TOTAL'!C22 -> Acarreo Vertical | D22: =+'TAREO ACTIVIDADES TOTAL'!D22 -> Traslado Vertical y Horizontal | E22: =SUM(F22:AJ22) -> 0
B23: =B22+1 -> 17 | C23: =+'TAREO ACTIVIDADES TOTAL'!C23 -> Forjado de escaleras en sotano | D23: =+'TAREO ACTIVIDADES TOTAL'!D23 -> Contrapiso y Acabados en Cemento | E23: =SUM(F23:AJ23) -> 0
B24: =B23+1 -> 18 | C24: =+'TAREO ACTIVIDADES TOTAL'!C24 -> Bimastil | D24: =+'TAREO ACTIVIDADES TOTAL'!D24 -> Marmol, Granito, Cuarzo | E24: =SUM(F24:AJ24) -> 0
B25: =B24+1 -> 19 | C25: =+'TAREO ACTIVIDADES TOTAL'!C25 -> colocacion bordes pvc en escaleras | D25: =+'TAREO ACTIVIDADES TOTAL'!D25 -> varios arquitectura | E25: =SUM(F25:AJ25) -> 0
B26: =B25+1 -> 20 | C26: =+'TAREO ACTIVIDADES TOTAL'!C26 -> Asentado de ladrillo remates sotanos | D26: =+'TAREO ACTIVIDADES TOTAL'!D26 -> Muros de Albañileria | E26: =SUM(F26:AJ26) -> 0
B27: =B26+1 -> 21 | C27: =+'TAREO ACTIVIDADES TOTAL'!C27 -> Copado resanes y limpieza de vigas y columnas de fachada | D27: =+'TAREO ACTIVIDADES TOTAL'!D27 -> Pintura y recubrimiento | E27: =SUM(F27:AJ27) -> 0
B28: =B27+1 -> 22 | C28: =+'TAREO ACTIVIDADES TOTAL'!C28 -> Resane en sotanos pisos y muros | D28: =+'TAREO ACTIVIDADES TOTAL'!D28 -> Tarrajeo, Revoques y Enlucido | E28: =SUM(F28:AJ28) -> 0
... B51: =B50+1 -> 45 | C51: =+'TAREO ACTIVIDADES TOTAL'!C51 -> forrado de pisos spc | D51: =+'TAREO ACTIVIDADES TOTAL'!D51 -> Otros Formatos de Pisos | E51: =SUM(F51:AJ51) -> 0
B52: =B51+1 -> 46 | C52: =+'TAREO ACTIVIDADES TOTAL'!C52 -> Colocacion de topellantas en sotanos | D52: =+'TAREO ACTIVIDADES TOTAL'!D52 -> Varios - Arquitectura | E52: =SUM(F52:AJ52) -> 0 | AK52: anclaje en ductos
B53: =B52+1 -> 47 | C53: =+'TAREO ACTIVIDADES TOTAL'!C53 -> Solaqueos en montantes iiee iiss gas | D53: =+'TAREO ACTIVIDADES TOTAL'!D53 -> Tarrajeo, Revoques y Enlucido | E53: =SUM(F53:AJ53) -> 0
B54: =B53+1 -> 48 | C54: =+'TAREO ACTIVIDADES TOTAL'!C54 -> Siliconeado de muebles de melamine - cocinas, closet | D54: =+'TAREO ACTIVIDADES TOTAL'!D54 -> Carpinteria de Melamina | E54: =SUM(F54:AJ54) -> 0
B55: =B54+1 -> 49 | C55: =+'TAREO ACTIVIDADES TOTAL'!C55 -> Tarrajeo de banco de medidores | D55: =+'TAREO ACTIVIDADES TOTAL'!D55 -> Tarrajeo, Revoques y Enlucido | E55: =SUM(F55:AJ55) -> 0
B56: =B55+1 -> 50 | C56: =+'TAREO ACTIVIDADES TOTAL'!C56 -> dado de concreto acelografo | D56: =+'TAREO ACTIVIDADES TOTAL'!D56 -> varios arquitectura | E56: =SUM(F56:AJ56) -> 0
B57: =B56+1 -> 51 | C57: =+'TAREO ACTIVIDADES TOTAL'!C57 -> nicho para control de riego piso 16 | D57: =+'TAREO ACTIVIDADES TOTAL'!D57 -> varios arquitectura | E57: =SUM(F57:AJ57) -> 0
B58: =B57+1 -> 52 | C58: =+'TAREO ACTIVIDADES TOTAL'!C58 -> Forrado de enchape de baños | D58: =+'TAREO ACTIVIDADES TOTAL'!D58 -> Pisos de enchape ceramico y porcelanato | E58: =SUM(F58:AJ58) -> 0
B59: =B58+1 -> 53 | C59: =+'TAREO ACTIVIDADES TOTAL'!C59 -> Trazo en fachada para ventanas | D59: =+'TAREO ACTIVIDADES TOTAL'!D59 -> Topografia | E59: =SUM(F59:AJ59) -> 0
B60: =B59+1 -> 54 | C60: =+'TAREO ACTIVIDADES TOTAL'!C60 -> Corte de fierro con instalacion de ventanas | D60: =+'TAREO ACTIVIDADES TOTAL'!D60 -> Seguridad Industrial (EPP y EPC), Patrimonial | E60: =SUM(F60:AJ60) -> 0
B61: =B60+1 -> 55 | C61: =+'TAREO ACTIVIDADES TOTAL'!C61 -> Encofrado y concreto lobby | D61: =+'TAREO ACTIVIDADES TOTAL'!D61 -> Varios - Arquitectura | E61: =SUM(F61:AJ61) -> 0
B62: =B61+1 -> 56 | C62: =+'TAREO ACTIVIDADES TOTAL'!C62 -> Tarrajeos de derrames y resanes en dpts | D62: =+'TAREO ACTIVIDADES TOTAL'!D62 -> Tarrajeo, Revoques y Enlucido | E62: =SUM(F62:AJ62) -> 0
B63: =B62+1 -> 57 | C63: =+'TAREO ACTIVIDADES TOTAL'!C63 -> Acentado ladrillo blanco piso 1 | D63: =+'TAREO ACTIVIDADES TOTAL'!D63 -> Varios - Arquitectura | E63: =SUM(F63:AJ63) -> 0
B64: =B63+1 -> 58 | C64: =+'TAREO ACTIVIDADES TOTAL'!C64 -> Tarrajeos derrames solaqueo techo tecnico | D64: =+'TAREO ACTIVIDADES TOTAL'!D64 -> Tarrajeo, Revoques y Enlucido | E64: =SUM(F64:AJ64) -> 0
...

Sheet TAREO MIERCOLES
B2: TAREO DE DIARIO OBRERO POR ACTIVIDAD
B3: CLIENTE | C3: INVERSIONES SAURIS SAC | N3: FECHA: | O3: =+'TAREO MARTES'!O3:AP3+1 -> 45713 | AQ3: OBSERVACIONES
B5: ITEM | C5: TRABAJADOR | D5: PARTIDA DE CONTROL | E5: TOTAL DE HORAS POR ACTIVIDAD | F5: =+CONCATENATE('TAREO SEMANAL'!$B11," ",'TAREO SEMANAL'!$C11) -> PEREZ GALLEGOS JORGE ANDRES | G5: =+CONCATENATE('TAREO SEMANAL'!$B12," ",'TAREO SEMANAL'!$C12) -> SANCHEZ BUSTAMANTE DAVID GONZALO | H5: =+CONCATENATE('TAREO SEMANAL'!$B13," ",'TAREO SEMANAL'!$C13) -> SANDOVAL CONDORI VICTOR ANGEL | I5: =+CONCATENATE('TAREO SEMANAL'!$B14," ",'TAREO SEMANAL'!$C14) -> ELME MORAN JOHN JORGE | J5: =+CONCATENATE('TAREO SEMANAL'!$B15," ",'TAREO SEMANAL'!$C15) -> ELME CURIPACO DIETRICH RODRIGO | K5: =+CONCATENATE('TAREO SEMANAL'!$B16," ",'TAREO SEMANAL'!$C16) -> CHUQUILIN ANGULO OSCAR JUNIOR | L5: =+CONCATENATE('TAREO SEMANAL'!$B17," ",'TAREO SEMANAL'!$C17) | M5: =+CONCATENATE('TAREO SEMANAL'!$B18," ",'TAREO SEMANAL'!$C18) | N5: =+CONCATENATE('TAREO SEMANAL'!$B19," ",'TAREO SEMANAL'!$C19) | O5: =+CONCATENATE('TAREO SEMANAL'!$B20," ",'TAREO SEMANAL'!$C20) | P5: =+CONCATENATE('TAREO SEMANAL'!$B21," ",'TAREO SEMANAL'!$C21) | Q5: =+CONCATENATE('TAREO SEMANAL'!$B22," ",'TAREO SEMANAL'!$C22) | R5: =+CONCATENATE('TAREO SEMANAL'!$B23," ",'TAREO SEMANAL'!$C23) | S5: =+CONCATENATE('TAREO SEMANAL'!$B24," ",'TAREO SEMANAL'!$C24) | T5: =+CONCATENATE('TAREO SEMANAL'!$B25," ",'TAREO SEMANAL'!$C25) | U5: =+CONCATENATE('TAREO SEMANAL'!$B26," ",'TAREO SEMANAL'!$C26) | V5: =+CONCATENATE('TAREO SEMANAL'!$B27," ",'TAREO SEMANAL'!$C27) | W5: =+CONCATENATE('TAREO SEMANAL'!$B28," ",'TAREO SEMANAL'!$C28) | X5: =+CONCATENATE('TAREO SEMANAL'!$B29," ",'TAREO SEMANAL'!$C29) | Y5: =+CONCATENATE('TAREO SEMANAL'!$B30," ",'TAREO SEMANAL'!$C30) | Z5: =+CONCATENATE('TAREO SEMANAL'!$B31," ",'TAREO SEMANAL'!$C31) | AA5: =+CONCATENATE('TAREO SEMANAL'!$B32," ",'TAREO SEMANAL'!$C32) | AB5: =+CONCATENATE('TAREO SEMANAL'!$B33," ",'TAREO SEMANAL'!$C33) | AC5: =+CONCATENATE('TAREO SEMANAL'!$B34," ",'TAREO SEMANAL'!$C34) | AD5: =+CONCATENATE('TAREO SEMANAL'!$B35," ",'TAREO SEMANAL'!$C35) | AE5: =+CONCATENATE('TAREO SEMANAL'!$B36," ",'TAREO SEMANAL'!$C36) | AF5: =+CONCATENATE('TAREO SEMANAL'!$B37," ",'TAREO SEMANAL'!$C37) | AG5: =+CONCATENATE('TAREO SEMANAL'!$B38," ",'TAREO SEMANAL'!$C38) | AH5: =+CONCATENATE('TAREO SEMANAL'!$B39," ",'TAREO SEMANAL'!$C39) | AI5: =+CONCATENATE('TAREO SEMANAL'!$B40," ",'TAREO SEMANAL'!$C40) | AJ5: =+CONCATENATE('TAREO SEMANAL'!$B41," ",'TAREO SEMANAL'!$C41)
C6: ACTIVIDAD | F6: 1 | G6: =+F6+1 -> 2 | H6: =+G6+1 -> 3 | I6: =+H6+1 -> 4 | J6: =+I6+1 -> 5 | K6: =+J6+1 -> 6 | L6: =+K6+1 -> 7 | M6: =+L6+1 -> 8 | N6: =+M6+1 -> 9 | O6: =+N6+1 -> 10 | P6: 11 | Q6: =+P6+1 -> 12 | R6: =+Q6+1 -> 13 | S6: 14 | T6: =+S6+1 -> 15 | U6: =+T6+1 -> 16 | V6: =+U6+1 -> 17 | W6: 18 | X6: =+W6+1 -> 19 | Y6: 20 | Z6: 21 | AA6: 22 | AB6: 23 | AC6: 24 | AD6: 25 | AE6: 26 | AF6: 27 | AG6: 28 | AH6: 29 | AI6: 30 | AJ6: 38
B7: 1 | C7: =+'TAREO ACTIVIDADES TOTAL'!C7 -> Trabajos provisionales almacen | D7: =+'TAREO ACTIVIDADES TOTAL'!D7 -> Obras provosionales | E7: =SUM(F7:AJ7) -> 0
B8: =B7+1 -> 2 | C8: =+'TAREO ACTIVIDADES TOTAL'!C8 -> vigia | D8: =+'TAREO ACTIVIDADES TOTAL'!D8 -> Seguridad Industrial (EPP y EPC), Patrimonial | E8: =SUM(F8:AJ8) -> 8.5 | F8: 8.5
B9: =B8+1 -> 3 | C9: =+'TAREO ACTIVIDADES TOTAL'!C9 -> monitor | D9: =+'TAREO ACTIVIDADES TOTAL'!D9 -> Seguridad Industrial (EPP y EPC), Patrimonial | E9: =SUM(F9:AJ9) -> 8.5 | K9: 8.5
B10: =B9+1 -> 4 | C10: =+'TAREO ACTIVIDADES TOTAL'!C10 -> Limpieza de obra | D10: =+'TAREO ACTIVIDADES TOTAL'!D10 -> Varios - Obras Provisionales | E10: =SUM(F10:AJ10) -> 0
B11: =B10+1 -> 5 | C11: =+'TAREO ACTIVIDADES TOTAL'!C11 -> SNDICATO | D11: =+'TAREO ACTIVIDADES TOTAL'!D11 -> Seguridad Industrial (EPP y EPC), Patrimonial | E11: =SUM(F11:AJ11) -> 8.5 | H11: 8.5
B12: =B11+1 -> 6 | C12: =+'TAREO ACTIVIDADES TOTAL'!C12 -> cerco perimetrico provicional | D12: =+'TAREO ACTIVIDADES TOTAL'!D12 -> Obras provosionales | E12: =SUM(F12:AJ12) -> 0 | AK12: picado con rotomartillo
B13: =B12+1 -> 7 | C13: =+'TAREO ACTIVIDADES TOTAL'!C13 -> Trabajos provicionales - oficina staff - Almacen | D13: =+'TAREO ACTIVIDADES TOTAL'!D13 -> Caseta para Oficinas, comedor y Cerco perimetrico | E13: =SUM(F13:AJ13) -> 0
B14: =B13+1 -> 8 | C14: =+'TAREO ACTIVIDADES TOTAL'!C14 -> Trabajos provicionales - baños | D14: =+'TAREO ACTIVIDADES TOTAL'!D14 -> Servicios Higienicos para Staff y Obreros | E14: =SUM(F14:AJ14) -> 0
B15: =B14+1 -> 9 | C15: =+'TAREO ACTIVIDADES TOTAL'!C15 -> Señalizacion de obra | D15: =+'TAREO ACTIVIDADES TOTAL'!D15 -> Seguridad Industrial (EPP y EPC), Patrimonial | E15: =SUM(F15:AJ15) -> 4 | G15: 4
B16: =B15+1 -> 10 | C16: =+'TAREO ACTIVIDADES TOTAL'!C16 -> Topografia | D16: =+'TAREO ACTIVIDADES TOTAL'!D16 -> Topografia | E16: =SUM(F16:AJ16) -> 17 | I16: 8.5 | J16: 8.5
B17: =B16+1 -> 11 | C17: =+'TAREO ACTIVIDADES TOTAL'!C17 -> Protecciones colectivas | D17: =+'TAREO ACTIVIDADES TOTAL'!D17 -> Seguridad Industrial (EPP y EPC), Patrimonial | E17: =SUM(F17:AJ17) -> 0
B18: =B17+1 -> 12 | C18: =+'TAREO ACTIVIDADES TOTAL'!C18 -> Limpieza de vecinos | D18: =+'TAREO ACTIVIDADES TOTAL'!D18 -> Varios - Obras Provisionales | E18: =SUM(F18:AJ18) -> 0
B19: =B18+1 -> 13 | C19: =+'TAREO ACTIVIDADES TOTAL'!C19 -> Traslado de materiales de Almacen | D19: =+'TAREO ACTIVIDADES TOTAL'!D19 -> Traslado Vertical y Horizontal | E19: =SUM(F19:AJ19) -> 0
B20: =B19+1 -> 14 | C20: =+'TAREO ACTIVIDADES TOTAL'!C20 -> umedecer terreno | D20: =+'TAREO ACTIVIDADES TOTAL'!D20 -> movimientos de tierra | E20: =SUM(F20:AJ20) -> 4.5 | G20: 4.5
B21: =B20+1 -> 15 | C21: =+'TAREO ACTIVIDADES TOTAL'!C21 -> Acarreo Horizontal | D21: =+'TAREO ACTIVIDADES TOTAL'!D21 -> Traslado Vertical y Horizontal | E21: =SUM(F21:AJ21) -> 0
B22: =B21+1 -> 16 | C22: =+'TAREO ACTIVIDADES TOTAL'!C22 -> Acarreo Vertical | D22: =+'TAREO ACTIVIDADES TOTAL'!D22 -> Traslado Vertical y Horizontal | E22: =SUM(F22:AJ22) -> 0
B23: =B22+1 -> 17 | C23: =+'TAREO ACTIVIDADES TOTAL'!C23 -> Forjado de escaleras en sotano | D23: =+'TAREO ACTIVIDADES TOTAL'!D23 -> Contrapiso y Acabados en Cemento | E23: =SUM(F23:AJ23) -> 0
B24: =B23+1 -> 18 | C24: =+'TAREO ACTIVIDADES TOTAL'!C24 -> Bimastil | D24: =+'TAREO ACTIVIDADES TOTAL'!D24 -> Marmol, Granito, Cuarzo | E24: =SUM(F24:AJ24) -> 0
B25: =B24+1 -> 19 | C25: =+'TAREO ACTIVIDADES TOTAL'!C25 -> colocacion bordes pvc en escaleras | D25: =+'TAREO ACTIVIDADES TOTAL'!D25 -> varios arquitectura | E25: =SUM(F25:AJ25) -> 0
B26: =B25+1 -> 20 | C26: =+'TAREO ACTIVIDADES TOTAL'!C26 -> Asentado de ladrillo remates sotanos | D26: =+'TAREO ACTIVIDADES TOTAL'!D26 -> Muros de Albañileria | E26: =SUM(F26:AJ26) -> 0
B27: =B26+1 -> 21 | C27: =+'TAREO ACTIVIDADES TOTAL'!C27 -> Copado resanes y limpieza de vigas y columnas de fachada | D27: =+'TAREO ACTIVIDADES TOTAL'!D27 -> Pintura y recubrimiento | E27: =SUM(F27:AJ27) -> 0
B28: =B27+1 -> 22 | C28: =+'TAREO ACTIVIDADES TOTAL'!C28 -> Resane en sotanos pisos y muros | D28: =+'TAREO ACTIVIDADES TOTAL'!D28 -> Tarrajeo, Revoques y Enlucido | E28: =SUM(F28:AJ28) -> 0
B29: =B28+1 -> 23 | C29: =+'TAREO ACTIVIDADES TOTAL'!C29 -> Capataz de acabados | D29: =+'TAREO ACTIVIDADES TOTAL'!D29 -> Gastos de personal | E29: =SUM(F29:AJ29) -> 0
B30: =B29+1 -> 24 | C30: =+'TAREO ACTIVIDADES TOTAL'!C30 -> Encofradoy concreto en ductos en montantes | D30: =+'TAREO ACTIVIDADES TOTAL'!D30 -> Muros de Albañileria | E30: =SUM(F30:AJ30) -> 0
B31: =B30+1 -> 25 | C31: =+'TAREO ACTIVIDADES TOTAL'!C31 -> resanes en casa vecinas | D31: =+'TAREO ACTIVIDADES TOTAL'!D31 -> varios arquitectura | E31: =SUM(F31:AJ31) -> 0
B32: =B31+1 -> 26 | C32: =+'TAREO ACTIVIDADES TOTAL'!C32 -> resanes piso 16 | D32: =+'TAREO ACTIVIDADES TOTAL'!D32 -> Tarrajeo, Revoques y Enlucido | E32: =SUM(F32:AJ32) -> 0
... B71: =B70+1 -> 65 | C71: =+'TAREO ACTIVIDADES TOTAL'!C71 -> Colocacion ladrillo adoquines | D71: =+'TAREO ACTIVIDADES TOTAL'!D71 -> otros obras exteriores | E71: =SUM(F71:AJ71) -> 0
B72: =B71+1 -> 66 | C72: COCRETO RANPA BUÑADO | D72: =+'TAREO ACTIVIDADES TOTAL'!D72 -> otros obras exteriores | E72: =SUM(F72:AJ72) -> 0
B73: =B72+1 -> 67 | C73: =+'TAREO ACTIVIDADES TOTAL'!C73 -> Concreto jardinera y sardineles exteriores | D73: =+'TAREO ACTIVIDADES TOTAL'!D73 -> Otros, Obras Exteriores | E73: =SUM(F73:AJ73) -> 0
B74: =B73+1 -> 68 | C74: =+'TAREO ACTIVIDADES TOTAL'!C74 -> Enchapes fachada | D74: =+'TAREO ACTIVIDADES TOTAL'!D74 -> Pisos de enchape ceramico y porcelanato | E74: =SUM(F74:AJ74) -> 0
B75: =B74+1 -> 69 | C75: =+'TAREO ACTIVIDADES TOTAL'!C75 -> Colocacion de señaletias | D75: =+'TAREO ACTIVIDADES TOTAL'!D75 -> Varios - Arquitectura | E75: =SUM(F75:AJ75) -> 0
B76: =B75+1 -> 70 | C76: =+'TAREO ACTIVIDADES TOTAL'!C76 -> 0 | D76: =+'TAREO ACTIVIDADES TOTAL'!D76 -> 0 | E76: =SUM(F76:AJ76) -> 0
B77: TOTAL DE HORAS POR TRABAJADOR | E77: =SUM(E7:E76) -> 51 | F77: =SUM(F7:F76) -> 8.5 | G77: =SUM(G7:G76) -> 8.5 | H77: =SUM(H7:H76) -> 8.5 | I77: =SUM(I7:I76) -> 8.5 | J77: =SUM(J7:J76) -> 8.5 | K77: =SUM(K7:K76) -> 8.5 | L77: =SUM(L7:L76) -> 0 | ... N77: =SUM(N7:N76) -> 0 | O77: 0 | Q77: 0 | V77: 0 | W77: 0 | X77: 0 | Z77: 0 | AA77: 0 | AE77: 0 | AF77: 0 | AG77: 0 | AH77: =SUM(AH7:AH76) -> 0 | AI77: =SUM(AI7:AI76) -> 0 | AJ77: 0

Sheet TAREO JUEVES
B2: TAREO DE DIARIO OBRERO POR ACTIVIDAD
B3: CLIENTE | C3: INVERSIONES SAURIS SAC | N3: FECHA: | O3: =+'TAREO MIERCOLES'!O3:AP3+1 -> 45714 | AQ3: OBSERVACIONES
B5: ITEM | C5: TRABAJADOR | D5: PARTIDA DE CONTROL | E5: TOTAL DE HORAS POR ACTIVIDAD | F5: =+CONCATENATE('TAREO SEMANAL'!$B11," ",'TAREO SEMANAL'!$C11) -> PEREZ GALLEGOS JORGE ANDRES | G5: =+CONCATENATE('TAREO SEMANAL'!$B12," ",'TAREO SEMANAL'!$C12) -> SANCHEZ BUSTAMANTE DAVID GONZALO | H5: =+CONCATENATE('TAREO SEMANAL'!$B13," ",'TAREO SEMANAL'!$C13) -> SANDOVAL CONDORI VICTOR ANGEL | I5: =+CONCATENATE('TAREO SEMANAL'!$B14," ",'TAREO SEMANAL'!$C14) -> ELME MORAN JOHN JORGE | J5: =+CONCATENATE('TAREO SEMANAL'!$B15," ",'TAREO SEMANAL'!$C15) -> ELME CURIPACO DIETRICH RODRIGO | K5: =+CONCATENATE('TAREO SEMANAL'!$B16," ",'TAREO SEMANAL'!$C16) -> CHUQUILIN ANGULO OSCAR JUNIOR | L5: =+CONCATENATE('TAREO SEMANAL'!$B17," ",'TAREO SEMANAL'!$C17) | M5: =+CONCATENATE('TAREO SEMANAL'!$B18," ",'TAREO SEMANAL'!$C18) | N5: =+CONCATENATE('TAREO SEMANAL'!$B19," ",'TAREO SEMANAL'!$C19) | O5: =+CONCATENATE('TAREO SEMANAL'!$B20," ",'TAREO SEMANAL'!$C20) | P5: =+CONCATENATE('TAREO SEMANAL'!$B21," ",'TAREO SEMANAL'!$C21) | Q5: =+CONCATENATE('TAREO SEMANAL'!$B22," ",'TAREO SEMANAL'!$C22) | R5: =+CONCATENATE('TAREO SEMANAL'!$B23," ",'TAREO SEMANAL'!$C23) | S5: =+CONCATENATE('TAREO SEMANAL'!$B24," ",'TAREO SEMANAL'!$C24) | T5: =+CONCATENATE('TAREO SEMANAL'!$B25," ",'TAREO SEMANAL'!$C25) | U5: =+CONCATENATE('TAREO SEMANAL'!$B26," ",'TAREO SEMANAL'!$C26) | V5: =+CONCATENATE('TAREO SEMANAL'!$B27," ",'TAREO SEMANAL'!$C27) | W5: =+CONCATENATE('TAREO SEMANAL'!$B28," ",'TAREO SEMANAL'!$C28) | X5: =+CONCATENATE('TAREO SEMANAL'!$B29," ",'TAREO SEMANAL'!$C29) | Y5: =+CONCATENATE('TAREO SEMANAL'!$B30," ",'TAREO SEMANAL'!$C30) | Z5: =+CONCATENATE('TAREO SEMANAL'!$B31," ",'TAREO SEMANAL'!$C31) | AA5: =+CONCATENATE('TAREO SEMANAL'!$B32," ",'TAREO SEMANAL'!$C32) | AB5: =+CONCATENATE('TAREO SEMANAL'!$B33," ",'TAREO SEMANAL'!$C33) | AC5: =+CONCATENATE('TAREO SEMANAL'!$B34," ",'TAREO SEMANAL'!$C34) | AD5: =+CONCATENATE('TAREO SEMANAL'!$B35," ",'TAREO SEMANAL'!$C35) | AE5: =+CONCATENATE('TAREO SEMANAL'!$B36," ",'TAREO SEMANAL'!$C36) | AF5: =+CONCATENATE('TAREO SEMANAL'!$B37," ",'TAREO SEMANAL'!$C37) | AG5: =+CONCATENATE('TAREO SEMANAL'!$B38," ",'TAREO SEMANAL'!$C38) | AH5: =+CONCATENATE('TAREO SEMANAL'!$B39," ",'TAREO SEMANAL'!$C39) | AI5: =+CONCATENATE('TAREO SEMANAL'!$B40," ",'TAREO SEMANAL'!$C40) | AJ5: =+CONCATENATE('TAREO SEMANAL'!$B41," ",'TAREO SEMANAL'!$C41)
C6: ACTIVIDAD | F6: 1 | G6: =+F6+1 -> 2 | H6: =+G6+1 -> 3 | I6: =+H6+1 -> 4 | J6: =+I6+1 -> 5 | K6: =+J6+1 -> 6 | L6: =+K6+1 -> 7 | M6: =+L6+1 -> 8 | N6: =+M6+1 -> 9 | O6: =+N6+1 -> 10 | P6: 11 | Q6: =+P6+1 -> 12 | R6: =+Q6+1 -> 13 | S6: 14 | T6: =+S6+1 -> 15 | U6: =+T6+1 -> 16 | V6: 17 | W6: 18 | X6: 19 | Y6: 20 | Z6: 21 | AA6: 22 | AB6: 23 | AC6: 24 | AD6: 25 | AE6: 26 | AF6: 27 | AG6: 28 | AH6: 29 | AI6: 30 | AJ6: 38
B7: 1 | C7: =+'TAREO ACTIVIDADES TOTAL'!C7 -> Trabajos provisionales almacen | D7: =+'TAREO ACTIVIDADES TOTAL'!D7 -> Obras provosionales | E7: =SUM(F7:AJ7) -> 0
B8: =B7+1 -> 2 | C8: =+'TAREO ACTIVIDADES TOTAL'!C8 -> vigia | D8: =+'TAREO ACTIVIDADES TOTAL'!D8 -> Seguridad Industrial (EPP y EPC), Patrimonial | E8: =SUM(F8:AJ8) -> 17 | F8: 8.5 | K8: 8.5
B9: =B8+1 -> 3 | C9: =+'TAREO ACTIVIDADES TOTAL'!C9 -> monitor | D9: =+'TAREO ACTIVIDADES TOTAL'!D9 -> Seguridad Industrial (EPP y EPC), Patrimonial | E9: =SUM(F9:AJ9) -> 0
B10: =B9+1 -> 4 | C10: =+'TAREO ACTIVIDADES TOTAL'!C10 -> Limpieza de obra | D10: =+'TAREO ACTIVIDADES TOTAL'!D10 -> Varios - Obras Provisionales | E10: =SUM(F10:AJ10) -> 0
B11: =B10+1 -> 5 | C11: =+'TAREO ACTIVIDADES TOTAL'!C11 -> SNDICATO | D11: =+'TAREO ACTIVIDADES TOTAL'!D11 -> Seguridad Industrial (EPP y EPC), Patrimonial | E11: =SUM(F11:AJ11) -> 8.5 | H11: 8.5
B12: =B11+1 -> 6 | C12: =+'TAREO ACTIVIDADES TOTAL'!C12 -> cerco perimetrico provicional | D12: =+'TAREO ACTIVIDADES TOTAL'!D12 -> Obras provosionales | E12: =SUM(F12:AJ12) -> 0
B13: =B12+1 -> 7 | C13: =+'TAREO ACTIVIDADES TOTAL'!C13 -> Trabajos provicionales - oficina staff - Almacen | D13: =+'TAREO ACTIVIDADES TOTAL'!D13 -> Caseta para Oficinas, comedor y Cerco perimetrico | E13: =SUM(F13:AJ13) -> 0 | AK13: picado ducto asensor
B14: =B13+1 -> 8 | C14: =+'TAREO ACTIVIDADES TOTAL'!C14 -> Trabajos provicionales - baños | D14: =+'TAREO ACTIVIDADES TOTAL'!D14 -> Servicios Higienicos para Staff y Obreros | E14: =SUM(F14:AJ14) -> 0
B15: =B14+1 -> 9 | C15: =+'TAREO ACTIVIDADES TOTAL'!C15 -> Señalizacion de obra | D15: =+'TAREO ACTIVIDADES TOTAL'!D15 -> Seguridad Industrial (EPP y EPC), Patrimonial | E15: =SUM(F15:AJ15) -> 4 | G15: 4
B16: =B15+1 -> 10 | C16: =+'TAREO ACTIVIDADES TOTAL'!C16 -> Topografia | D16: =+'TAREO ACTIVIDADES TOTAL'!D16 -> Topografia | E16: =SUM(F16:AJ16) -> 17 | I16: 8.5 | J16: 8.5
B17: =B16+1 -> 11 | C17: =+'TAREO ACTIVIDADES TOTAL'!C17 -> Protecciones colectivas | D17: =+'TAREO ACTIVIDADES TOTAL'!D17 -> Seguridad Industrial (EPP y EPC), Patrimonial | E17: =SUM(F17:AJ17) -> 0
B18: =B17+1 -> 12 | C18: =+'TAREO ACTIVIDADES TOTAL'!C18 -> Limpieza de vecinos | D18: =+'TAREO ACTIVIDADES TOTAL'!D18 -> Varios - Obras Provisionales | E18: =SUM(F18:AJ18) -> 0
B19: =B18+1 -> 13 | C19: =+'TAREO ACTIVIDADES TOTAL'!C19 -> Traslado de materiales de Almacen | D19: =+'TAREO ACTIVIDADES TOTAL'!D19 -> Traslado Vertical y Horizontal | E19: =SUM(F19:AJ19) -> 0
B20: =B19+1 -> 14 | C20: =+'TAREO ACTIVIDADES TOTAL'!C20 -> umedecer terreno | D20: =+'TAREO ACTIVIDADES TOTAL'!D20 -> movimientos de tierra | E20: =SUM(F20:AJ20) -> 4.5 | G20: 4.5
B21: =B20+1 -> 15 | C21: =+'TAREO ACTIVIDADES TOTAL'!C21 -> Acarreo Horizontal | D21: =+'TAREO ACTIVIDADES TOTAL'!D21 -> Traslado Vertical y Horizontal | E21: =SUM(F21:AJ21) -> 0
B22: =B21+1 -> 16 | C22: =+'TAREO ACTIVIDADES TOTAL'!C22 -> Acarreo Vertical | D22: =+'TAREO ACTIVIDADES TOTAL'!D22 -> Traslado Vertical y Horizontal | E22: =SUM(F22:AJ22) -> 0
B23: =B22+1 -> 17 | C23: =+'TAREO ACTIVIDADES TOTAL'!C23 -> Forjado de escaleras en sotano | D23: =+'TAREO ACTIVIDADES TOTAL'!D23 -> Contrapiso y Acabados en Cemento | E23: =SUM(F23:AJ23) -> 0
B24: =B23+1 -> 18 | C24: =+'TAREO ACTIVIDADES TOTAL'!C24 -> Bimastil | D24: =+'TAREO ACTIVIDADES TOTAL'!D24 -> Marmol, Granito, Cuarzo | E24: =SUM(F24:AJ24) -> 0
B25: =B24+1 -> 19 | C25: =+'TAREO ACTIVIDADES TOTAL'!C25 -> colocacion bordes pvc en escaleras | D25: =+'TAREO ACTIVIDADES TOTAL'!D25 -> varios arquitectura | E25: =SUM(F25:AJ25) -> 0
B26: =B25+1 -> 20 | C26: =+'TAREO ACTIVIDADES TOTAL'!C26 -> Asentado de ladrillo remates sotanos | D26: =+'TAREO ACTIVIDADES TOTAL'!D26 -> Muros de Albañileria | E26: =SUM(F26:AJ26) -> 0
